{
 "cells": [
  {
   "cell_type": "code",
   "execution_count": 1,
   "metadata": {},
   "outputs": [
    {
     "data": {
      "text/html": [
       "<style>.container { width:90% !important; }</style>"
      ],
      "text/plain": [
       "<IPython.core.display.HTML object>"
      ]
     },
     "metadata": {},
     "output_type": "display_data"
    }
   ],
   "source": [
    "from IPython.display import IFrame\n",
    "from IPython.core.display import display, HTML\n",
    "display(HTML(\"<style>.container { width:90% !important; }</style>\"))"
   ]
  },
  {
   "cell_type": "code",
   "execution_count": 2,
   "metadata": {},
   "outputs": [],
   "source": [
    "import app"
   ]
  },
  {
   "cell_type": "code",
   "execution_count": 3,
   "metadata": {},
   "outputs": [
    {
     "name": "stderr",
     "output_type": "stream",
     "text": [
      " * Running on http://127.0.0.1:8050/ (Press CTRL+C to quit)\n",
      "[2018-06-26 15:54:34,380] ERROR in app: Exception on /_dash-update-component [POST]\n",
      "Traceback (most recent call last):\n",
      "  File \"/usr/local/lib/python2.7/dist-packages/flask/app.py\", line 1982, in wsgi_app\n",
      "    response = self.full_dispatch_request()\n",
      "  File \"/usr/local/lib/python2.7/dist-packages/flask/app.py\", line 1614, in full_dispatch_request\n",
      "    rv = self.handle_user_exception(e)\n",
      "  File \"/usr/local/lib/python2.7/dist-packages/flask/app.py\", line 1517, in handle_user_exception\n",
      "    reraise(exc_type, exc_value, tb)\n",
      "  File \"/usr/local/lib/python2.7/dist-packages/flask/app.py\", line 1612, in full_dispatch_request\n",
      "    rv = self.dispatch_request()\n",
      "  File \"/usr/local/lib/python2.7/dist-packages/flask/app.py\", line 1598, in dispatch_request\n",
      "    return self.view_functions[rule.endpoint](**req.view_args)\n",
      "  File \"/usr/local/lib/python2.7/dist-packages/dash/dash.py\", line 556, in dispatch\n",
      "    return self.callback_map[target_id]['callback'](*args)\n",
      "  File \"/usr/local/lib/python2.7/dist-packages/dash/dash.py\", line 513, in add_context\n",
      "    output_value = func(*args, **kwargs)\n",
      "  File \"app.py\", line 117, in gen_cost\n",
      "    child = \"Test data: %f\" % get_cost()\n",
      "  File \"app.py\", line 110, in get_cost\n",
      "    cost += random.random()\n",
      "NameError: global name 'random' is not defined\n",
      "127.0.0.1 - - [26/Jun/2018 15:54:34] \"\u001b[1m\u001b[35mPOST /_dash-update-component HTTP/1.1\u001b[0m\" 500 -\n",
      "[2018-06-26 15:54:34,388] ERROR in app: Exception on /_dash-update-component [POST]\n",
      "Traceback (most recent call last):\n",
      "  File \"/usr/local/lib/python2.7/dist-packages/flask/app.py\", line 1982, in wsgi_app\n",
      "    response = self.full_dispatch_request()\n",
      "  File \"/usr/local/lib/python2.7/dist-packages/flask/app.py\", line 1614, in full_dispatch_request\n",
      "    rv = self.handle_user_exception(e)\n",
      "  File \"/usr/local/lib/python2.7/dist-packages/flask/app.py\", line 1517, in handle_user_exception\n",
      "    reraise(exc_type, exc_value, tb)\n",
      "  File \"/usr/local/lib/python2.7/dist-packages/flask/app.py\", line 1612, in full_dispatch_request\n",
      "    rv = self.dispatch_request()\n",
      "  File \"/usr/local/lib/python2.7/dist-packages/flask/app.py\", line 1598, in dispatch_request\n",
      "    return self.view_functions[rule.endpoint](**req.view_args)\n",
      "  File \"/usr/local/lib/python2.7/dist-packages/dash/dash.py\", line 556, in dispatch\n",
      "    return self.callback_map[target_id]['callback'](*args)\n",
      "  File \"/usr/local/lib/python2.7/dist-packages/dash/dash.py\", line 513, in add_context\n",
      "    output_value = func(*args, **kwargs)\n",
      "  File \"app.py\", line 131, in gen_loss\n",
      "    x=get_xs(),\n",
      "NameError: global name 'get_xs' is not defined\n",
      "127.0.0.1 - - [26/Jun/2018 15:54:34] \"\u001b[1m\u001b[35mPOST /_dash-update-component HTTP/1.1\u001b[0m\" 500 -\n",
      "[2018-06-26 15:54:34,427] ERROR in app: Exception on /_dash-update-component [POST]\n",
      "Traceback (most recent call last):\n",
      "  File \"/usr/local/lib/python2.7/dist-packages/flask/app.py\", line 1982, in wsgi_app\n",
      "    response = self.full_dispatch_request()\n",
      "  File \"/usr/local/lib/python2.7/dist-packages/flask/app.py\", line 1614, in full_dispatch_request\n",
      "    rv = self.handle_user_exception(e)\n",
      "  File \"/usr/local/lib/python2.7/dist-packages/flask/app.py\", line 1517, in handle_user_exception\n",
      "    reraise(exc_type, exc_value, tb)\n",
      "  File \"/usr/local/lib/python2.7/dist-packages/flask/app.py\", line 1612, in full_dispatch_request\n",
      "    rv = self.dispatch_request()\n",
      "  File \"/usr/local/lib/python2.7/dist-packages/flask/app.py\", line 1598, in dispatch_request\n",
      "    return self.view_functions[rule.endpoint](**req.view_args)\n",
      "  File \"/usr/local/lib/python2.7/dist-packages/dash/dash.py\", line 556, in dispatch\n",
      "    return self.callback_map[target_id]['callback'](*args)\n",
      "  File \"/usr/local/lib/python2.7/dist-packages/dash/dash.py\", line 513, in add_context\n",
      "    output_value = func(*args, **kwargs)\n",
      "  File \"app.py\", line 117, in gen_cost\n",
      "    child = \"Test data: %f\" % get_cost()\n",
      "  File \"app.py\", line 110, in get_cost\n",
      "    cost += random.random()\n",
      "NameError: global name 'random' is not defined\n",
      "127.0.0.1 - - [26/Jun/2018 15:54:34] \"\u001b[1m\u001b[35mPOST /_dash-update-component HTTP/1.1\u001b[0m\" 500 -\n",
      "[2018-06-26 15:54:34,433] ERROR in app: Exception on /_dash-update-component [POST]\n",
      "Traceback (most recent call last):\n",
      "  File \"/usr/local/lib/python2.7/dist-packages/flask/app.py\", line 1982, in wsgi_app\n",
      "    response = self.full_dispatch_request()\n",
      "  File \"/usr/local/lib/python2.7/dist-packages/flask/app.py\", line 1614, in full_dispatch_request\n",
      "    rv = self.handle_user_exception(e)\n",
      "  File \"/usr/local/lib/python2.7/dist-packages/flask/app.py\", line 1517, in handle_user_exception\n",
      "    reraise(exc_type, exc_value, tb)\n",
      "  File \"/usr/local/lib/python2.7/dist-packages/flask/app.py\", line 1612, in full_dispatch_request\n",
      "    rv = self.dispatch_request()\n",
      "  File \"/usr/local/lib/python2.7/dist-packages/flask/app.py\", line 1598, in dispatch_request\n",
      "    return self.view_functions[rule.endpoint](**req.view_args)\n",
      "  File \"/usr/local/lib/python2.7/dist-packages/dash/dash.py\", line 556, in dispatch\n",
      "    return self.callback_map[target_id]['callback'](*args)\n",
      "  File \"/usr/local/lib/python2.7/dist-packages/dash/dash.py\", line 513, in add_context\n",
      "    output_value = func(*args, **kwargs)\n",
      "  File \"app.py\", line 131, in gen_loss\n",
      "    x=get_xs(),\n",
      "NameError: global name 'get_xs' is not defined\n",
      "127.0.0.1 - - [26/Jun/2018 15:54:34] \"\u001b[1m\u001b[35mPOST /_dash-update-component HTTP/1.1\u001b[0m\" 500 -\n",
      "[2018-06-26 15:54:36,084] ERROR in app: Exception on /_dash-update-component [POST]\n",
      "Traceback (most recent call last):\n",
      "  File \"/usr/local/lib/python2.7/dist-packages/flask/app.py\", line 1982, in wsgi_app\n",
      "    response = self.full_dispatch_request()\n",
      "  File \"/usr/local/lib/python2.7/dist-packages/flask/app.py\", line 1614, in full_dispatch_request\n",
      "    rv = self.handle_user_exception(e)\n",
      "  File \"/usr/local/lib/python2.7/dist-packages/flask/app.py\", line 1517, in handle_user_exception\n",
      "    reraise(exc_type, exc_value, tb)\n",
      "  File \"/usr/local/lib/python2.7/dist-packages/flask/app.py\", line 1612, in full_dispatch_request\n",
      "    rv = self.dispatch_request()\n",
      "  File \"/usr/local/lib/python2.7/dist-packages/flask/app.py\", line 1598, in dispatch_request\n",
      "    return self.view_functions[rule.endpoint](**req.view_args)\n",
      "  File \"/usr/local/lib/python2.7/dist-packages/dash/dash.py\", line 556, in dispatch\n",
      "    return self.callback_map[target_id]['callback'](*args)\n",
      "  File \"/usr/local/lib/python2.7/dist-packages/dash/dash.py\", line 513, in add_context\n",
      "    output_value = func(*args, **kwargs)\n",
      "  File \"app.py\", line 131, in gen_loss\n",
      "    x=get_xs(),\n",
      "NameError: global name 'get_xs' is not defined\n",
      "127.0.0.1 - - [26/Jun/2018 15:54:36] \"\u001b[1m\u001b[35mPOST /_dash-update-component HTTP/1.1\u001b[0m\" 500 -\n",
      "[2018-06-26 15:54:36,092] ERROR in app: Exception on /_dash-update-component [POST]\n",
      "Traceback (most recent call last):\n",
      "  File \"/usr/local/lib/python2.7/dist-packages/flask/app.py\", line 1982, in wsgi_app\n",
      "    response = self.full_dispatch_request()\n",
      "  File \"/usr/local/lib/python2.7/dist-packages/flask/app.py\", line 1614, in full_dispatch_request\n",
      "    rv = self.handle_user_exception(e)\n",
      "  File \"/usr/local/lib/python2.7/dist-packages/flask/app.py\", line 1517, in handle_user_exception\n",
      "    reraise(exc_type, exc_value, tb)\n",
      "  File \"/usr/local/lib/python2.7/dist-packages/flask/app.py\", line 1612, in full_dispatch_request\n",
      "    rv = self.dispatch_request()\n",
      "  File \"/usr/local/lib/python2.7/dist-packages/flask/app.py\", line 1598, in dispatch_request\n",
      "    return self.view_functions[rule.endpoint](**req.view_args)\n",
      "  File \"/usr/local/lib/python2.7/dist-packages/dash/dash.py\", line 556, in dispatch\n",
      "    return self.callback_map[target_id]['callback'](*args)\n",
      "  File \"/usr/local/lib/python2.7/dist-packages/dash/dash.py\", line 513, in add_context\n",
      "    output_value = func(*args, **kwargs)\n",
      "  File \"app.py\", line 117, in gen_cost\n",
      "    child = \"Test data: %f\" % get_cost()\n",
      "  File \"app.py\", line 110, in get_cost\n",
      "    cost += random.random()\n",
      "NameError: global name 'random' is not defined\n",
      "127.0.0.1 - - [26/Jun/2018 15:54:36] \"\u001b[1m\u001b[35mPOST /_dash-update-component HTTP/1.1\u001b[0m\" 500 -\n",
      "[2018-06-26 15:54:37,410] ERROR in app: Exception on /_dash-update-component [POST]\n",
      "Traceback (most recent call last):\n",
      "  File \"/usr/local/lib/python2.7/dist-packages/flask/app.py\", line 1982, in wsgi_app\n",
      "    response = self.full_dispatch_request()\n",
      "  File \"/usr/local/lib/python2.7/dist-packages/flask/app.py\", line 1614, in full_dispatch_request\n",
      "    rv = self.handle_user_exception(e)\n",
      "  File \"/usr/local/lib/python2.7/dist-packages/flask/app.py\", line 1517, in handle_user_exception\n",
      "    reraise(exc_type, exc_value, tb)\n",
      "  File \"/usr/local/lib/python2.7/dist-packages/flask/app.py\", line 1612, in full_dispatch_request\n",
      "    rv = self.dispatch_request()\n",
      "  File \"/usr/local/lib/python2.7/dist-packages/flask/app.py\", line 1598, in dispatch_request\n",
      "    return self.view_functions[rule.endpoint](**req.view_args)\n",
      "  File \"/usr/local/lib/python2.7/dist-packages/dash/dash.py\", line 556, in dispatch\n",
      "    return self.callback_map[target_id]['callback'](*args)\n",
      "  File \"/usr/local/lib/python2.7/dist-packages/dash/dash.py\", line 513, in add_context\n",
      "    output_value = func(*args, **kwargs)\n",
      "  File \"app.py\", line 117, in gen_cost\n",
      "    child = \"Test data: %f\" % get_cost()\n",
      "  File \"app.py\", line 110, in get_cost\n",
      "    cost += random.random()\n",
      "NameError: global name 'random' is not defined\n"
     ]
    },
    {
     "name": "stderr",
     "output_type": "stream",
     "text": [
      "127.0.0.1 - - [26/Jun/2018 15:54:37] \"\u001b[1m\u001b[35mPOST /_dash-update-component HTTP/1.1\u001b[0m\" 500 -\n",
      "[2018-06-26 15:54:37,416] ERROR in app: Exception on /_dash-update-component [POST]\n",
      "Traceback (most recent call last):\n",
      "  File \"/usr/local/lib/python2.7/dist-packages/flask/app.py\", line 1982, in wsgi_app\n",
      "    response = self.full_dispatch_request()\n",
      "  File \"/usr/local/lib/python2.7/dist-packages/flask/app.py\", line 1614, in full_dispatch_request\n",
      "    rv = self.handle_user_exception(e)\n",
      "  File \"/usr/local/lib/python2.7/dist-packages/flask/app.py\", line 1517, in handle_user_exception\n",
      "    reraise(exc_type, exc_value, tb)\n",
      "  File \"/usr/local/lib/python2.7/dist-packages/flask/app.py\", line 1612, in full_dispatch_request\n",
      "    rv = self.dispatch_request()\n",
      "  File \"/usr/local/lib/python2.7/dist-packages/flask/app.py\", line 1598, in dispatch_request\n",
      "    return self.view_functions[rule.endpoint](**req.view_args)\n",
      "  File \"/usr/local/lib/python2.7/dist-packages/dash/dash.py\", line 556, in dispatch\n",
      "    return self.callback_map[target_id]['callback'](*args)\n",
      "  File \"/usr/local/lib/python2.7/dist-packages/dash/dash.py\", line 513, in add_context\n",
      "    output_value = func(*args, **kwargs)\n",
      "  File \"app.py\", line 131, in gen_loss\n",
      "    x=get_xs(),\n",
      "NameError: global name 'get_xs' is not defined\n",
      "127.0.0.1 - - [26/Jun/2018 15:54:37] \"\u001b[1m\u001b[35mPOST /_dash-update-component HTTP/1.1\u001b[0m\" 500 -\n",
      "[2018-06-26 15:54:37,447] ERROR in app: Exception on /_dash-update-component [POST]\n",
      "Traceback (most recent call last):\n",
      "  File \"/usr/local/lib/python2.7/dist-packages/flask/app.py\", line 1982, in wsgi_app\n",
      "    response = self.full_dispatch_request()\n",
      "  File \"/usr/local/lib/python2.7/dist-packages/flask/app.py\", line 1614, in full_dispatch_request\n",
      "    rv = self.handle_user_exception(e)\n",
      "  File \"/usr/local/lib/python2.7/dist-packages/flask/app.py\", line 1517, in handle_user_exception\n",
      "    reraise(exc_type, exc_value, tb)\n",
      "  File \"/usr/local/lib/python2.7/dist-packages/flask/app.py\", line 1612, in full_dispatch_request\n",
      "    rv = self.dispatch_request()\n",
      "  File \"/usr/local/lib/python2.7/dist-packages/flask/app.py\", line 1598, in dispatch_request\n",
      "    return self.view_functions[rule.endpoint](**req.view_args)\n",
      "  File \"/usr/local/lib/python2.7/dist-packages/dash/dash.py\", line 556, in dispatch\n",
      "    return self.callback_map[target_id]['callback'](*args)\n",
      "  File \"/usr/local/lib/python2.7/dist-packages/dash/dash.py\", line 513, in add_context\n",
      "    output_value = func(*args, **kwargs)\n",
      "  File \"app.py\", line 117, in gen_cost\n",
      "    child = \"Test data: %f\" % get_cost()\n",
      "  File \"app.py\", line 110, in get_cost\n",
      "    cost += random.random()\n",
      "NameError: global name 'random' is not defined\n",
      "127.0.0.1 - - [26/Jun/2018 15:54:37] \"\u001b[1m\u001b[35mPOST /_dash-update-component HTTP/1.1\u001b[0m\" 500 -\n",
      "[2018-06-26 15:54:37,452] ERROR in app: Exception on /_dash-update-component [POST]\n",
      "Traceback (most recent call last):\n",
      "  File \"/usr/local/lib/python2.7/dist-packages/flask/app.py\", line 1982, in wsgi_app\n",
      "    response = self.full_dispatch_request()\n",
      "  File \"/usr/local/lib/python2.7/dist-packages/flask/app.py\", line 1614, in full_dispatch_request\n",
      "    rv = self.handle_user_exception(e)\n",
      "  File \"/usr/local/lib/python2.7/dist-packages/flask/app.py\", line 1517, in handle_user_exception\n",
      "    reraise(exc_type, exc_value, tb)\n",
      "  File \"/usr/local/lib/python2.7/dist-packages/flask/app.py\", line 1612, in full_dispatch_request\n",
      "    rv = self.dispatch_request()\n",
      "  File \"/usr/local/lib/python2.7/dist-packages/flask/app.py\", line 1598, in dispatch_request\n",
      "    return self.view_functions[rule.endpoint](**req.view_args)\n",
      "  File \"/usr/local/lib/python2.7/dist-packages/dash/dash.py\", line 556, in dispatch\n",
      "    return self.callback_map[target_id]['callback'](*args)\n",
      "  File \"/usr/local/lib/python2.7/dist-packages/dash/dash.py\", line 513, in add_context\n",
      "    output_value = func(*args, **kwargs)\n",
      "  File \"app.py\", line 131, in gen_loss\n",
      "    x=get_xs(),\n",
      "NameError: global name 'get_xs' is not defined\n",
      "127.0.0.1 - - [26/Jun/2018 15:54:37] \"\u001b[1m\u001b[35mPOST /_dash-update-component HTTP/1.1\u001b[0m\" 500 -\n",
      "[2018-06-26 15:54:39,080] ERROR in app: Exception on /_dash-update-component [POST]\n",
      "Traceback (most recent call last):\n",
      "  File \"/usr/local/lib/python2.7/dist-packages/flask/app.py\", line 1982, in wsgi_app\n",
      "    response = self.full_dispatch_request()\n",
      "  File \"/usr/local/lib/python2.7/dist-packages/flask/app.py\", line 1614, in full_dispatch_request\n",
      "    rv = self.handle_user_exception(e)\n",
      "  File \"/usr/local/lib/python2.7/dist-packages/flask/app.py\", line 1517, in handle_user_exception\n",
      "    reraise(exc_type, exc_value, tb)\n",
      "  File \"/usr/local/lib/python2.7/dist-packages/flask/app.py\", line 1612, in full_dispatch_request\n",
      "    rv = self.dispatch_request()\n",
      "  File \"/usr/local/lib/python2.7/dist-packages/flask/app.py\", line 1598, in dispatch_request\n",
      "    return self.view_functions[rule.endpoint](**req.view_args)\n",
      "  File \"/usr/local/lib/python2.7/dist-packages/dash/dash.py\", line 556, in dispatch\n",
      "    return self.callback_map[target_id]['callback'](*args)\n",
      "  File \"/usr/local/lib/python2.7/dist-packages/dash/dash.py\", line 513, in add_context\n",
      "    output_value = func(*args, **kwargs)\n",
      "  File \"app.py\", line 131, in gen_loss\n",
      "    x=get_xs(),\n",
      "NameError: global name 'get_xs' is not defined\n",
      "127.0.0.1 - - [26/Jun/2018 15:54:39] \"\u001b[1m\u001b[35mPOST /_dash-update-component HTTP/1.1\u001b[0m\" 500 -\n",
      "[2018-06-26 15:54:39,100] ERROR in app: Exception on /_dash-update-component [POST]\n",
      "Traceback (most recent call last):\n",
      "  File \"/usr/local/lib/python2.7/dist-packages/flask/app.py\", line 1982, in wsgi_app\n",
      "    response = self.full_dispatch_request()\n",
      "  File \"/usr/local/lib/python2.7/dist-packages/flask/app.py\", line 1614, in full_dispatch_request\n",
      "    rv = self.handle_user_exception(e)\n",
      "  File \"/usr/local/lib/python2.7/dist-packages/flask/app.py\", line 1517, in handle_user_exception\n",
      "    reraise(exc_type, exc_value, tb)\n",
      "  File \"/usr/local/lib/python2.7/dist-packages/flask/app.py\", line 1612, in full_dispatch_request\n",
      "    rv = self.dispatch_request()\n",
      "  File \"/usr/local/lib/python2.7/dist-packages/flask/app.py\", line 1598, in dispatch_request\n",
      "    return self.view_functions[rule.endpoint](**req.view_args)\n",
      "  File \"/usr/local/lib/python2.7/dist-packages/dash/dash.py\", line 556, in dispatch\n",
      "    return self.callback_map[target_id]['callback'](*args)\n",
      "  File \"/usr/local/lib/python2.7/dist-packages/dash/dash.py\", line 513, in add_context\n",
      "    output_value = func(*args, **kwargs)\n",
      "  File \"app.py\", line 117, in gen_cost\n",
      "    child = \"Test data: %f\" % get_cost()\n",
      "  File \"app.py\", line 110, in get_cost\n",
      "    cost += random.random()\n",
      "NameError: global name 'random' is not defined\n",
      "127.0.0.1 - - [26/Jun/2018 15:54:39] \"\u001b[1m\u001b[35mPOST /_dash-update-component HTTP/1.1\u001b[0m\" 500 -\n",
      "[2018-06-26 15:54:40,441] ERROR in app: Exception on /_dash-update-component [POST]\n",
      "Traceback (most recent call last):\n",
      "  File \"/usr/local/lib/python2.7/dist-packages/flask/app.py\", line 1982, in wsgi_app\n",
      "    response = self.full_dispatch_request()\n",
      "  File \"/usr/local/lib/python2.7/dist-packages/flask/app.py\", line 1614, in full_dispatch_request\n",
      "    rv = self.handle_user_exception(e)\n",
      "  File \"/usr/local/lib/python2.7/dist-packages/flask/app.py\", line 1517, in handle_user_exception\n",
      "    reraise(exc_type, exc_value, tb)\n",
      "  File \"/usr/local/lib/python2.7/dist-packages/flask/app.py\", line 1612, in full_dispatch_request\n",
      "    rv = self.dispatch_request()\n",
      "  File \"/usr/local/lib/python2.7/dist-packages/flask/app.py\", line 1598, in dispatch_request\n",
      "    return self.view_functions[rule.endpoint](**req.view_args)\n",
      "  File \"/usr/local/lib/python2.7/dist-packages/dash/dash.py\", line 556, in dispatch\n",
      "    return self.callback_map[target_id]['callback'](*args)\n",
      "  File \"/usr/local/lib/python2.7/dist-packages/dash/dash.py\", line 513, in add_context\n",
      "    output_value = func(*args, **kwargs)\n",
      "  File \"app.py\", line 117, in gen_cost\n",
      "    child = \"Test data: %f\" % get_cost()\n",
      "  File \"app.py\", line 110, in get_cost\n",
      "    cost += random.random()\n",
      "NameError: global name 'random' is not defined\n",
      "127.0.0.1 - - [26/Jun/2018 15:54:40] \"\u001b[1m\u001b[35mPOST /_dash-update-component HTTP/1.1\u001b[0m\" 500 -\n",
      "[2018-06-26 15:54:40,448] ERROR in app: Exception on /_dash-update-component [POST]\n",
      "Traceback (most recent call last):\n",
      "  File \"/usr/local/lib/python2.7/dist-packages/flask/app.py\", line 1982, in wsgi_app\n",
      "    response = self.full_dispatch_request()\n",
      "  File \"/usr/local/lib/python2.7/dist-packages/flask/app.py\", line 1614, in full_dispatch_request\n",
      "    rv = self.handle_user_exception(e)\n",
      "  File \"/usr/local/lib/python2.7/dist-packages/flask/app.py\", line 1517, in handle_user_exception\n",
      "    reraise(exc_type, exc_value, tb)\n",
      "  File \"/usr/local/lib/python2.7/dist-packages/flask/app.py\", line 1612, in full_dispatch_request\n",
      "    rv = self.dispatch_request()\n",
      "  File \"/usr/local/lib/python2.7/dist-packages/flask/app.py\", line 1598, in dispatch_request\n",
      "    return self.view_functions[rule.endpoint](**req.view_args)\n",
      "  File \"/usr/local/lib/python2.7/dist-packages/dash/dash.py\", line 556, in dispatch\n",
      "    return self.callback_map[target_id]['callback'](*args)\n",
      "  File \"/usr/local/lib/python2.7/dist-packages/dash/dash.py\", line 513, in add_context\n",
      "    output_value = func(*args, **kwargs)\n",
      "  File \"app.py\", line 131, in gen_loss\n",
      "    x=get_xs(),\n",
      "NameError: global name 'get_xs' is not defined\n"
     ]
    },
    {
     "name": "stderr",
     "output_type": "stream",
     "text": [
      "127.0.0.1 - - [26/Jun/2018 15:54:40] \"\u001b[1m\u001b[35mPOST /_dash-update-component HTTP/1.1\u001b[0m\" 500 -\n",
      "[2018-06-26 15:54:40,596] ERROR in app: Exception on /_dash-update-component [POST]\n",
      "Traceback (most recent call last):\n",
      "  File \"/usr/local/lib/python2.7/dist-packages/flask/app.py\", line 1982, in wsgi_app\n",
      "    response = self.full_dispatch_request()\n",
      "  File \"/usr/local/lib/python2.7/dist-packages/flask/app.py\", line 1614, in full_dispatch_request\n",
      "    rv = self.handle_user_exception(e)\n",
      "  File \"/usr/local/lib/python2.7/dist-packages/flask/app.py\", line 1517, in handle_user_exception\n",
      "    reraise(exc_type, exc_value, tb)\n",
      "  File \"/usr/local/lib/python2.7/dist-packages/flask/app.py\", line 1612, in full_dispatch_request\n",
      "    rv = self.dispatch_request()\n",
      "  File \"/usr/local/lib/python2.7/dist-packages/flask/app.py\", line 1598, in dispatch_request\n",
      "    return self.view_functions[rule.endpoint](**req.view_args)\n",
      "  File \"/usr/local/lib/python2.7/dist-packages/dash/dash.py\", line 556, in dispatch\n",
      "    return self.callback_map[target_id]['callback'](*args)\n",
      "  File \"/usr/local/lib/python2.7/dist-packages/dash/dash.py\", line 513, in add_context\n",
      "    output_value = func(*args, **kwargs)\n",
      "  File \"app.py\", line 117, in gen_cost\n",
      "    child = \"Test data: %f\" % get_cost()\n",
      "  File \"app.py\", line 110, in get_cost\n",
      "    cost += random.random()\n",
      "NameError: global name 'random' is not defined\n",
      "127.0.0.1 - - [26/Jun/2018 15:54:40] \"\u001b[1m\u001b[35mPOST /_dash-update-component HTTP/1.1\u001b[0m\" 500 -\n",
      "[2018-06-26 15:54:40,614] ERROR in app: Exception on /_dash-update-component [POST]\n",
      "Traceback (most recent call last):\n",
      "  File \"/usr/local/lib/python2.7/dist-packages/flask/app.py\", line 1982, in wsgi_app\n",
      "    response = self.full_dispatch_request()\n",
      "  File \"/usr/local/lib/python2.7/dist-packages/flask/app.py\", line 1614, in full_dispatch_request\n",
      "    rv = self.handle_user_exception(e)\n",
      "  File \"/usr/local/lib/python2.7/dist-packages/flask/app.py\", line 1517, in handle_user_exception\n",
      "    reraise(exc_type, exc_value, tb)\n",
      "  File \"/usr/local/lib/python2.7/dist-packages/flask/app.py\", line 1612, in full_dispatch_request\n",
      "    rv = self.dispatch_request()\n",
      "  File \"/usr/local/lib/python2.7/dist-packages/flask/app.py\", line 1598, in dispatch_request\n",
      "    return self.view_functions[rule.endpoint](**req.view_args)\n",
      "  File \"/usr/local/lib/python2.7/dist-packages/dash/dash.py\", line 556, in dispatch\n",
      "    return self.callback_map[target_id]['callback'](*args)\n",
      "  File \"/usr/local/lib/python2.7/dist-packages/dash/dash.py\", line 513, in add_context\n",
      "    output_value = func(*args, **kwargs)\n",
      "  File \"app.py\", line 131, in gen_loss\n",
      "    x=get_xs(),\n",
      "NameError: global name 'get_xs' is not defined\n",
      "127.0.0.1 - - [26/Jun/2018 15:54:40] \"\u001b[1m\u001b[35mPOST /_dash-update-component HTTP/1.1\u001b[0m\" 500 -\n",
      "[2018-06-26 15:54:42,066] ERROR in app: Exception on /_dash-update-component [POST]\n",
      "Traceback (most recent call last):\n",
      "  File \"/usr/local/lib/python2.7/dist-packages/flask/app.py\", line 1982, in wsgi_app\n",
      "    response = self.full_dispatch_request()\n",
      "  File \"/usr/local/lib/python2.7/dist-packages/flask/app.py\", line 1614, in full_dispatch_request\n",
      "    rv = self.handle_user_exception(e)\n",
      "  File \"/usr/local/lib/python2.7/dist-packages/flask/app.py\", line 1517, in handle_user_exception\n",
      "    reraise(exc_type, exc_value, tb)\n",
      "  File \"/usr/local/lib/python2.7/dist-packages/flask/app.py\", line 1612, in full_dispatch_request\n",
      "    rv = self.dispatch_request()\n",
      "  File \"/usr/local/lib/python2.7/dist-packages/flask/app.py\", line 1598, in dispatch_request\n",
      "    return self.view_functions[rule.endpoint](**req.view_args)\n",
      "  File \"/usr/local/lib/python2.7/dist-packages/dash/dash.py\", line 556, in dispatch\n",
      "    return self.callback_map[target_id]['callback'](*args)\n",
      "  File \"/usr/local/lib/python2.7/dist-packages/dash/dash.py\", line 513, in add_context\n",
      "    output_value = func(*args, **kwargs)\n",
      "  File \"app.py\", line 131, in gen_loss\n",
      "    x=get_xs(),\n",
      "NameError: global name 'get_xs' is not defined\n",
      "127.0.0.1 - - [26/Jun/2018 15:54:42] \"\u001b[1m\u001b[35mPOST /_dash-update-component HTTP/1.1\u001b[0m\" 500 -\n",
      "[2018-06-26 15:54:42,075] ERROR in app: Exception on /_dash-update-component [POST]\n",
      "Traceback (most recent call last):\n",
      "  File \"/usr/local/lib/python2.7/dist-packages/flask/app.py\", line 1982, in wsgi_app\n",
      "    response = self.full_dispatch_request()\n",
      "  File \"/usr/local/lib/python2.7/dist-packages/flask/app.py\", line 1614, in full_dispatch_request\n",
      "    rv = self.handle_user_exception(e)\n",
      "  File \"/usr/local/lib/python2.7/dist-packages/flask/app.py\", line 1517, in handle_user_exception\n",
      "    reraise(exc_type, exc_value, tb)\n",
      "  File \"/usr/local/lib/python2.7/dist-packages/flask/app.py\", line 1612, in full_dispatch_request\n",
      "    rv = self.dispatch_request()\n",
      "  File \"/usr/local/lib/python2.7/dist-packages/flask/app.py\", line 1598, in dispatch_request\n",
      "    return self.view_functions[rule.endpoint](**req.view_args)\n",
      "  File \"/usr/local/lib/python2.7/dist-packages/dash/dash.py\", line 556, in dispatch\n",
      "    return self.callback_map[target_id]['callback'](*args)\n",
      "  File \"/usr/local/lib/python2.7/dist-packages/dash/dash.py\", line 513, in add_context\n",
      "    output_value = func(*args, **kwargs)\n",
      "  File \"app.py\", line 117, in gen_cost\n",
      "    child = \"Test data: %f\" % get_cost()\n",
      "  File \"app.py\", line 110, in get_cost\n",
      "    cost += random.random()\n",
      "NameError: global name 'random' is not defined\n",
      "127.0.0.1 - - [26/Jun/2018 15:54:42] \"\u001b[1m\u001b[35mPOST /_dash-update-component HTTP/1.1\u001b[0m\" 500 -\n",
      "[2018-06-26 15:54:43,435] ERROR in app: Exception on /_dash-update-component [POST]\n",
      "Traceback (most recent call last):\n",
      "  File \"/usr/local/lib/python2.7/dist-packages/flask/app.py\", line 1982, in wsgi_app\n",
      "    response = self.full_dispatch_request()\n",
      "  File \"/usr/local/lib/python2.7/dist-packages/flask/app.py\", line 1614, in full_dispatch_request\n",
      "    rv = self.handle_user_exception(e)\n",
      "  File \"/usr/local/lib/python2.7/dist-packages/flask/app.py\", line 1517, in handle_user_exception\n",
      "    reraise(exc_type, exc_value, tb)\n",
      "  File \"/usr/local/lib/python2.7/dist-packages/flask/app.py\", line 1612, in full_dispatch_request\n",
      "    rv = self.dispatch_request()\n",
      "  File \"/usr/local/lib/python2.7/dist-packages/flask/app.py\", line 1598, in dispatch_request\n",
      "    return self.view_functions[rule.endpoint](**req.view_args)\n",
      "  File \"/usr/local/lib/python2.7/dist-packages/dash/dash.py\", line 556, in dispatch\n",
      "    return self.callback_map[target_id]['callback'](*args)\n",
      "  File \"/usr/local/lib/python2.7/dist-packages/dash/dash.py\", line 513, in add_context\n",
      "    output_value = func(*args, **kwargs)\n",
      "  File \"app.py\", line 117, in gen_cost\n",
      "    child = \"Test data: %f\" % get_cost()\n",
      "  File \"app.py\", line 110, in get_cost\n",
      "    cost += random.random()\n",
      "NameError: global name 'random' is not defined\n",
      "127.0.0.1 - - [26/Jun/2018 15:54:43] \"\u001b[1m\u001b[35mPOST /_dash-update-component HTTP/1.1\u001b[0m\" 500 -\n",
      "[2018-06-26 15:54:43,441] ERROR in app: Exception on /_dash-update-component [POST]\n",
      "Traceback (most recent call last):\n",
      "  File \"/usr/local/lib/python2.7/dist-packages/flask/app.py\", line 1982, in wsgi_app\n",
      "    response = self.full_dispatch_request()\n",
      "  File \"/usr/local/lib/python2.7/dist-packages/flask/app.py\", line 1614, in full_dispatch_request\n",
      "    rv = self.handle_user_exception(e)\n",
      "  File \"/usr/local/lib/python2.7/dist-packages/flask/app.py\", line 1517, in handle_user_exception\n",
      "    reraise(exc_type, exc_value, tb)\n",
      "  File \"/usr/local/lib/python2.7/dist-packages/flask/app.py\", line 1612, in full_dispatch_request\n",
      "    rv = self.dispatch_request()\n",
      "  File \"/usr/local/lib/python2.7/dist-packages/flask/app.py\", line 1598, in dispatch_request\n",
      "    return self.view_functions[rule.endpoint](**req.view_args)\n",
      "  File \"/usr/local/lib/python2.7/dist-packages/dash/dash.py\", line 556, in dispatch\n",
      "    return self.callback_map[target_id]['callback'](*args)\n",
      "  File \"/usr/local/lib/python2.7/dist-packages/dash/dash.py\", line 513, in add_context\n",
      "    output_value = func(*args, **kwargs)\n",
      "  File \"app.py\", line 131, in gen_loss\n",
      "    x=get_xs(),\n",
      "NameError: global name 'get_xs' is not defined\n",
      "127.0.0.1 - - [26/Jun/2018 15:54:43] \"\u001b[1m\u001b[35mPOST /_dash-update-component HTTP/1.1\u001b[0m\" 500 -\n",
      "[2018-06-26 15:54:43,575] ERROR in app: Exception on /_dash-update-component [POST]\n",
      "Traceback (most recent call last):\n",
      "  File \"/usr/local/lib/python2.7/dist-packages/flask/app.py\", line 1982, in wsgi_app\n",
      "    response = self.full_dispatch_request()\n",
      "  File \"/usr/local/lib/python2.7/dist-packages/flask/app.py\", line 1614, in full_dispatch_request\n",
      "    rv = self.handle_user_exception(e)\n",
      "  File \"/usr/local/lib/python2.7/dist-packages/flask/app.py\", line 1517, in handle_user_exception\n",
      "    reraise(exc_type, exc_value, tb)\n",
      "  File \"/usr/local/lib/python2.7/dist-packages/flask/app.py\", line 1612, in full_dispatch_request\n",
      "    rv = self.dispatch_request()\n",
      "  File \"/usr/local/lib/python2.7/dist-packages/flask/app.py\", line 1598, in dispatch_request\n",
      "    return self.view_functions[rule.endpoint](**req.view_args)\n",
      "  File \"/usr/local/lib/python2.7/dist-packages/dash/dash.py\", line 556, in dispatch\n",
      "    return self.callback_map[target_id]['callback'](*args)\n",
      "  File \"/usr/local/lib/python2.7/dist-packages/dash/dash.py\", line 513, in add_context\n",
      "    output_value = func(*args, **kwargs)\n",
      "  File \"app.py\", line 117, in gen_cost\n",
      "    child = \"Test data: %f\" % get_cost()\n",
      "  File \"app.py\", line 110, in get_cost\n",
      "    cost += random.random()\n",
      "NameError: global name 'random' is not defined\n"
     ]
    },
    {
     "name": "stderr",
     "output_type": "stream",
     "text": [
      "127.0.0.1 - - [26/Jun/2018 15:54:43] \"\u001b[1m\u001b[35mPOST /_dash-update-component HTTP/1.1\u001b[0m\" 500 -\n",
      "[2018-06-26 15:54:43,590] ERROR in app: Exception on /_dash-update-component [POST]\n",
      "Traceback (most recent call last):\n",
      "  File \"/usr/local/lib/python2.7/dist-packages/flask/app.py\", line 1982, in wsgi_app\n",
      "    response = self.full_dispatch_request()\n",
      "  File \"/usr/local/lib/python2.7/dist-packages/flask/app.py\", line 1614, in full_dispatch_request\n",
      "    rv = self.handle_user_exception(e)\n",
      "  File \"/usr/local/lib/python2.7/dist-packages/flask/app.py\", line 1517, in handle_user_exception\n",
      "    reraise(exc_type, exc_value, tb)\n",
      "  File \"/usr/local/lib/python2.7/dist-packages/flask/app.py\", line 1612, in full_dispatch_request\n",
      "    rv = self.dispatch_request()\n",
      "  File \"/usr/local/lib/python2.7/dist-packages/flask/app.py\", line 1598, in dispatch_request\n",
      "    return self.view_functions[rule.endpoint](**req.view_args)\n",
      "  File \"/usr/local/lib/python2.7/dist-packages/dash/dash.py\", line 556, in dispatch\n",
      "    return self.callback_map[target_id]['callback'](*args)\n",
      "  File \"/usr/local/lib/python2.7/dist-packages/dash/dash.py\", line 513, in add_context\n",
      "    output_value = func(*args, **kwargs)\n",
      "  File \"app.py\", line 131, in gen_loss\n",
      "    x=get_xs(),\n",
      "NameError: global name 'get_xs' is not defined\n",
      "127.0.0.1 - - [26/Jun/2018 15:54:43] \"\u001b[1m\u001b[35mPOST /_dash-update-component HTTP/1.1\u001b[0m\" 500 -\n",
      "[2018-06-26 15:54:45,108] ERROR in app: Exception on /_dash-update-component [POST]\n",
      "Traceback (most recent call last):\n",
      "  File \"/usr/local/lib/python2.7/dist-packages/flask/app.py\", line 1982, in wsgi_app\n",
      "    response = self.full_dispatch_request()\n",
      "  File \"/usr/local/lib/python2.7/dist-packages/flask/app.py\", line 1614, in full_dispatch_request\n",
      "    rv = self.handle_user_exception(e)\n",
      "  File \"/usr/local/lib/python2.7/dist-packages/flask/app.py\", line 1517, in handle_user_exception\n",
      "    reraise(exc_type, exc_value, tb)\n",
      "  File \"/usr/local/lib/python2.7/dist-packages/flask/app.py\", line 1612, in full_dispatch_request\n",
      "    rv = self.dispatch_request()\n",
      "  File \"/usr/local/lib/python2.7/dist-packages/flask/app.py\", line 1598, in dispatch_request\n",
      "    return self.view_functions[rule.endpoint](**req.view_args)\n",
      "  File \"/usr/local/lib/python2.7/dist-packages/dash/dash.py\", line 556, in dispatch\n",
      "    return self.callback_map[target_id]['callback'](*args)\n",
      "  File \"/usr/local/lib/python2.7/dist-packages/dash/dash.py\", line 513, in add_context\n",
      "    output_value = func(*args, **kwargs)\n",
      "  File \"app.py\", line 131, in gen_loss\n",
      "    x=get_xs(),\n",
      "NameError: global name 'get_xs' is not defined\n",
      "127.0.0.1 - - [26/Jun/2018 15:54:45] \"\u001b[1m\u001b[35mPOST /_dash-update-component HTTP/1.1\u001b[0m\" 500 -\n",
      "[2018-06-26 15:54:45,116] ERROR in app: Exception on /_dash-update-component [POST]\n",
      "Traceback (most recent call last):\n",
      "  File \"/usr/local/lib/python2.7/dist-packages/flask/app.py\", line 1982, in wsgi_app\n",
      "    response = self.full_dispatch_request()\n",
      "  File \"/usr/local/lib/python2.7/dist-packages/flask/app.py\", line 1614, in full_dispatch_request\n",
      "    rv = self.handle_user_exception(e)\n",
      "  File \"/usr/local/lib/python2.7/dist-packages/flask/app.py\", line 1517, in handle_user_exception\n",
      "    reraise(exc_type, exc_value, tb)\n",
      "  File \"/usr/local/lib/python2.7/dist-packages/flask/app.py\", line 1612, in full_dispatch_request\n",
      "    rv = self.dispatch_request()\n",
      "  File \"/usr/local/lib/python2.7/dist-packages/flask/app.py\", line 1598, in dispatch_request\n",
      "    return self.view_functions[rule.endpoint](**req.view_args)\n",
      "  File \"/usr/local/lib/python2.7/dist-packages/dash/dash.py\", line 556, in dispatch\n",
      "    return self.callback_map[target_id]['callback'](*args)\n",
      "  File \"/usr/local/lib/python2.7/dist-packages/dash/dash.py\", line 513, in add_context\n",
      "    output_value = func(*args, **kwargs)\n",
      "  File \"app.py\", line 117, in gen_cost\n",
      "    child = \"Test data: %f\" % get_cost()\n",
      "  File \"app.py\", line 110, in get_cost\n",
      "    cost += random.random()\n",
      "NameError: global name 'random' is not defined\n",
      "127.0.0.1 - - [26/Jun/2018 15:54:45] \"\u001b[1m\u001b[35mPOST /_dash-update-component HTTP/1.1\u001b[0m\" 500 -\n",
      "[2018-06-26 15:54:46,477] ERROR in app: Exception on /_dash-update-component [POST]\n",
      "Traceback (most recent call last):\n",
      "  File \"/usr/local/lib/python2.7/dist-packages/flask/app.py\", line 1982, in wsgi_app\n",
      "    response = self.full_dispatch_request()\n",
      "  File \"/usr/local/lib/python2.7/dist-packages/flask/app.py\", line 1614, in full_dispatch_request\n",
      "    rv = self.handle_user_exception(e)\n",
      "  File \"/usr/local/lib/python2.7/dist-packages/flask/app.py\", line 1517, in handle_user_exception\n",
      "    reraise(exc_type, exc_value, tb)\n",
      "  File \"/usr/local/lib/python2.7/dist-packages/flask/app.py\", line 1612, in full_dispatch_request\n",
      "    rv = self.dispatch_request()\n",
      "  File \"/usr/local/lib/python2.7/dist-packages/flask/app.py\", line 1598, in dispatch_request\n",
      "    return self.view_functions[rule.endpoint](**req.view_args)\n",
      "  File \"/usr/local/lib/python2.7/dist-packages/dash/dash.py\", line 556, in dispatch\n",
      "    return self.callback_map[target_id]['callback'](*args)\n",
      "  File \"/usr/local/lib/python2.7/dist-packages/dash/dash.py\", line 513, in add_context\n",
      "    output_value = func(*args, **kwargs)\n",
      "  File \"app.py\", line 117, in gen_cost\n",
      "    child = \"Test data: %f\" % get_cost()\n",
      "  File \"app.py\", line 110, in get_cost\n",
      "    cost += random.random()\n",
      "NameError: global name 'random' is not defined\n",
      "127.0.0.1 - - [26/Jun/2018 15:54:46] \"\u001b[1m\u001b[35mPOST /_dash-update-component HTTP/1.1\u001b[0m\" 500 -\n",
      "[2018-06-26 15:54:46,485] ERROR in app: Exception on /_dash-update-component [POST]\n",
      "Traceback (most recent call last):\n",
      "  File \"/usr/local/lib/python2.7/dist-packages/flask/app.py\", line 1982, in wsgi_app\n",
      "    response = self.full_dispatch_request()\n",
      "  File \"/usr/local/lib/python2.7/dist-packages/flask/app.py\", line 1614, in full_dispatch_request\n",
      "    rv = self.handle_user_exception(e)\n",
      "  File \"/usr/local/lib/python2.7/dist-packages/flask/app.py\", line 1517, in handle_user_exception\n",
      "    reraise(exc_type, exc_value, tb)\n",
      "  File \"/usr/local/lib/python2.7/dist-packages/flask/app.py\", line 1612, in full_dispatch_request\n",
      "    rv = self.dispatch_request()\n",
      "  File \"/usr/local/lib/python2.7/dist-packages/flask/app.py\", line 1598, in dispatch_request\n",
      "    return self.view_functions[rule.endpoint](**req.view_args)\n",
      "  File \"/usr/local/lib/python2.7/dist-packages/dash/dash.py\", line 556, in dispatch\n",
      "    return self.callback_map[target_id]['callback'](*args)\n",
      "  File \"/usr/local/lib/python2.7/dist-packages/dash/dash.py\", line 513, in add_context\n",
      "    output_value = func(*args, **kwargs)\n",
      "  File \"app.py\", line 131, in gen_loss\n",
      "    x=get_xs(),\n",
      "NameError: global name 'get_xs' is not defined\n",
      "127.0.0.1 - - [26/Jun/2018 15:54:46] \"\u001b[1m\u001b[35mPOST /_dash-update-component HTTP/1.1\u001b[0m\" 500 -\n",
      "[2018-06-26 15:54:46,623] ERROR in app: Exception on /_dash-update-component [POST]\n",
      "Traceback (most recent call last):\n",
      "  File \"/usr/local/lib/python2.7/dist-packages/flask/app.py\", line 1982, in wsgi_app\n",
      "    response = self.full_dispatch_request()\n",
      "  File \"/usr/local/lib/python2.7/dist-packages/flask/app.py\", line 1614, in full_dispatch_request\n",
      "    rv = self.handle_user_exception(e)\n",
      "  File \"/usr/local/lib/python2.7/dist-packages/flask/app.py\", line 1517, in handle_user_exception\n",
      "    reraise(exc_type, exc_value, tb)\n",
      "  File \"/usr/local/lib/python2.7/dist-packages/flask/app.py\", line 1612, in full_dispatch_request\n",
      "    rv = self.dispatch_request()\n",
      "  File \"/usr/local/lib/python2.7/dist-packages/flask/app.py\", line 1598, in dispatch_request\n",
      "    return self.view_functions[rule.endpoint](**req.view_args)\n",
      "  File \"/usr/local/lib/python2.7/dist-packages/dash/dash.py\", line 556, in dispatch\n",
      "    return self.callback_map[target_id]['callback'](*args)\n",
      "  File \"/usr/local/lib/python2.7/dist-packages/dash/dash.py\", line 513, in add_context\n",
      "    output_value = func(*args, **kwargs)\n",
      "  File \"app.py\", line 117, in gen_cost\n",
      "    child = \"Test data: %f\" % get_cost()\n",
      "  File \"app.py\", line 110, in get_cost\n",
      "    cost += random.random()\n",
      "NameError: global name 'random' is not defined\n",
      "127.0.0.1 - - [26/Jun/2018 15:54:46] \"\u001b[1m\u001b[35mPOST /_dash-update-component HTTP/1.1\u001b[0m\" 500 -\n",
      "[2018-06-26 15:54:46,629] ERROR in app: Exception on /_dash-update-component [POST]\n",
      "Traceback (most recent call last):\n",
      "  File \"/usr/local/lib/python2.7/dist-packages/flask/app.py\", line 1982, in wsgi_app\n",
      "    response = self.full_dispatch_request()\n",
      "  File \"/usr/local/lib/python2.7/dist-packages/flask/app.py\", line 1614, in full_dispatch_request\n",
      "    rv = self.handle_user_exception(e)\n",
      "  File \"/usr/local/lib/python2.7/dist-packages/flask/app.py\", line 1517, in handle_user_exception\n",
      "    reraise(exc_type, exc_value, tb)\n",
      "  File \"/usr/local/lib/python2.7/dist-packages/flask/app.py\", line 1612, in full_dispatch_request\n",
      "    rv = self.dispatch_request()\n",
      "  File \"/usr/local/lib/python2.7/dist-packages/flask/app.py\", line 1598, in dispatch_request\n",
      "    return self.view_functions[rule.endpoint](**req.view_args)\n",
      "  File \"/usr/local/lib/python2.7/dist-packages/dash/dash.py\", line 556, in dispatch\n",
      "    return self.callback_map[target_id]['callback'](*args)\n",
      "  File \"/usr/local/lib/python2.7/dist-packages/dash/dash.py\", line 513, in add_context\n",
      "    output_value = func(*args, **kwargs)\n",
      "  File \"app.py\", line 131, in gen_loss\n",
      "    x=get_xs(),\n",
      "NameError: global name 'get_xs' is not defined\n"
     ]
    },
    {
     "name": "stderr",
     "output_type": "stream",
     "text": [
      "127.0.0.1 - - [26/Jun/2018 15:54:46] \"\u001b[1m\u001b[35mPOST /_dash-update-component HTTP/1.1\u001b[0m\" 500 -\n",
      "[2018-06-26 15:54:48,107] ERROR in app: Exception on /_dash-update-component [POST]\n",
      "Traceback (most recent call last):\n",
      "  File \"/usr/local/lib/python2.7/dist-packages/flask/app.py\", line 1982, in wsgi_app\n",
      "    response = self.full_dispatch_request()\n",
      "  File \"/usr/local/lib/python2.7/dist-packages/flask/app.py\", line 1614, in full_dispatch_request\n",
      "    rv = self.handle_user_exception(e)\n",
      "  File \"/usr/local/lib/python2.7/dist-packages/flask/app.py\", line 1517, in handle_user_exception\n",
      "    reraise(exc_type, exc_value, tb)\n",
      "  File \"/usr/local/lib/python2.7/dist-packages/flask/app.py\", line 1612, in full_dispatch_request\n",
      "    rv = self.dispatch_request()\n",
      "  File \"/usr/local/lib/python2.7/dist-packages/flask/app.py\", line 1598, in dispatch_request\n",
      "    return self.view_functions[rule.endpoint](**req.view_args)\n",
      "  File \"/usr/local/lib/python2.7/dist-packages/dash/dash.py\", line 556, in dispatch\n",
      "    return self.callback_map[target_id]['callback'](*args)\n",
      "  File \"/usr/local/lib/python2.7/dist-packages/dash/dash.py\", line 513, in add_context\n",
      "    output_value = func(*args, **kwargs)\n",
      "  File \"app.py\", line 131, in gen_loss\n",
      "    x=get_xs(),\n",
      "NameError: global name 'get_xs' is not defined\n",
      "127.0.0.1 - - [26/Jun/2018 15:54:48] \"\u001b[1m\u001b[35mPOST /_dash-update-component HTTP/1.1\u001b[0m\" 500 -\n",
      "[2018-06-26 15:54:48,128] ERROR in app: Exception on /_dash-update-component [POST]\n",
      "Traceback (most recent call last):\n",
      "  File \"/usr/local/lib/python2.7/dist-packages/flask/app.py\", line 1982, in wsgi_app\n",
      "    response = self.full_dispatch_request()\n",
      "  File \"/usr/local/lib/python2.7/dist-packages/flask/app.py\", line 1614, in full_dispatch_request\n",
      "    rv = self.handle_user_exception(e)\n",
      "  File \"/usr/local/lib/python2.7/dist-packages/flask/app.py\", line 1517, in handle_user_exception\n",
      "    reraise(exc_type, exc_value, tb)\n",
      "  File \"/usr/local/lib/python2.7/dist-packages/flask/app.py\", line 1612, in full_dispatch_request\n",
      "    rv = self.dispatch_request()\n",
      "  File \"/usr/local/lib/python2.7/dist-packages/flask/app.py\", line 1598, in dispatch_request\n",
      "    return self.view_functions[rule.endpoint](**req.view_args)\n",
      "  File \"/usr/local/lib/python2.7/dist-packages/dash/dash.py\", line 556, in dispatch\n",
      "    return self.callback_map[target_id]['callback'](*args)\n",
      "  File \"/usr/local/lib/python2.7/dist-packages/dash/dash.py\", line 513, in add_context\n",
      "    output_value = func(*args, **kwargs)\n",
      "  File \"app.py\", line 117, in gen_cost\n",
      "    child = \"Test data: %f\" % get_cost()\n",
      "  File \"app.py\", line 110, in get_cost\n",
      "    cost += random.random()\n",
      "NameError: global name 'random' is not defined\n",
      "127.0.0.1 - - [26/Jun/2018 15:54:48] \"\u001b[1m\u001b[35mPOST /_dash-update-component HTTP/1.1\u001b[0m\" 500 -\n"
     ]
    }
   ],
   "source": []
  },
  {
   "cell_type": "code",
   "execution_count": null,
   "metadata": {},
   "outputs": [],
   "source": [
    "from IPython.display import IFrame\n",
    "IFrame('http://localhost:8050', width=1000, height=1000)"
   ]
  }
 ],
 "metadata": {
  "kernelspec": {
   "display_name": "Python 2",
   "language": "python",
   "name": "python2"
  },
  "language_info": {
   "codemirror_mode": {
    "name": "ipython",
    "version": 2
   },
   "file_extension": ".py",
   "mimetype": "text/x-python",
   "name": "python",
   "nbconvert_exporter": "python",
   "pygments_lexer": "ipython2",
   "version": "2.7.12"
  }
 },
 "nbformat": 4,
 "nbformat_minor": 2
}
