{
 "cells": [
  {
   "cell_type": "code",
   "execution_count": 34,
   "metadata": {},
   "outputs": [
    {
     "data": {
      "text/html": [
       "<style>.container { width:90% !important; }</style>"
      ],
      "text/plain": [
       "<IPython.core.display.HTML object>"
      ]
     },
     "metadata": {},
     "output_type": "display_data"
    }
   ],
   "source": [
    "from IPython.display import IFrame\n",
    "from IPython.core.display import display, HTML\n",
    "display(HTML(\"<style>.container { width:90% !important; }</style>\"))"
   ]
  },
  {
   "cell_type": "code",
   "execution_count": 35,
   "metadata": {},
   "outputs": [
    {
     "ename": "ImportError",
     "evalue": "No module named 'app'",
     "output_type": "error",
     "traceback": [
      "\u001b[0;31m---------------------------------------------------------------------------\u001b[0m",
      "\u001b[0;31mImportError\u001b[0m                               Traceback (most recent call last)",
      "\u001b[0;32m<ipython-input-35-b814559dda6b>\u001b[0m in \u001b[0;36m<module>\u001b[0;34m()\u001b[0m\n\u001b[0;32m----> 1\u001b[0;31m \u001b[0;32mimport\u001b[0m \u001b[0mapp\u001b[0m\u001b[0;34m\u001b[0m\u001b[0m\n\u001b[0m",
      "\u001b[0;31mImportError\u001b[0m: No module named 'app'"
     ]
    }
   ],
   "source": [
    "import app"
   ]
  },
  {
   "cell_type": "code",
   "execution_count": 25,
   "metadata": {},
   "outputs": [
    {
     "data": {
      "text/html": [
       "\n",
       "        <iframe\n",
       "            width=\"700\"\n",
       "            height=\"350\"\n",
       "            src=\"http://localhost:8050\"\n",
       "            frameborder=\"0\"\n",
       "            allowfullscreen\n",
       "        ></iframe>\n",
       "        "
      ],
      "text/plain": [
       "<IPython.lib.display.IFrame at 0x7faa441abac8>"
      ]
     },
     "metadata": {},
     "output_type": "display_data"
    },
    {
     "name": "stderr",
     "output_type": "stream",
     "text": [
      " * Running on http://127.0.0.1:8050/ (Press CTRL+C to quit)\n",
      "/usr/local/lib/python3.5/dist-packages/dash/resources.py:36: UserWarning:\n",
      "\n",
      "A local version of https://codepen.io/chriddyp/pen/bWLwgP.css is not available\n",
      "\n",
      "127.0.0.1 - - [26/Jun/2018 15:44:57] \"GET / HTTP/1.1\" 200 -\n",
      "127.0.0.1 - - [26/Jun/2018 15:44:57] \"GET /_dash-component-suites/dash_core_components/rc-slider@6.1.2.css?v=0.23.0 HTTP/1.1\" 200 -\n",
      "127.0.0.1 - - [26/Jun/2018 15:44:57] \"GET /_dash-component-suites/dash_core_components/react-select@1.0.0-rc.3.min.css?v=0.23.0 HTTP/1.1\" 200 -\n",
      "127.0.0.1 - - [26/Jun/2018 15:44:57] \"GET /_dash-component-suites/dash_core_components/react-virtualized@9.9.0.css?v=0.23.0 HTTP/1.1\" 200 -\n",
      "127.0.0.1 - - [26/Jun/2018 15:44:57] \"GET /_dash-component-suites/dash_core_components/react-virtualized-select@3.1.0.css?v=0.23.0 HTTP/1.1\" 200 -\n",
      "127.0.0.1 - - [26/Jun/2018 15:44:57] \"GET /_dash-component-suites/dash_core_components/react-dates@12.3.0.css?v=0.23.0 HTTP/1.1\" 200 -\n",
      "127.0.0.1 - - [26/Jun/2018 15:44:57] \"GET /_dash-component-suites/dash_renderer/react@15.4.2.min.js?v=0.13.0 HTTP/1.1\" 200 -\n",
      "127.0.0.1 - - [26/Jun/2018 15:44:57] \"GET /_dash-component-suites/dash_renderer/react-dom@15.4.2.min.js?v=0.13.0 HTTP/1.1\" 200 -\n",
      "127.0.0.1 - - [26/Jun/2018 15:44:57] \"GET /_dash-component-suites/dash_html_components/bundle.js?v=0.11.0 HTTP/1.1\" 200 -\n",
      "127.0.0.1 - - [26/Jun/2018 15:44:57] \"GET /_dash-component-suites/dash_core_components/plotly-1.38.0.min.js?v=0.23.0 HTTP/1.1\" 200 -\n",
      "127.0.0.1 - - [26/Jun/2018 15:44:57] \"GET /_dash-component-suites/dash_core_components/bundle.js?v=0.23.0 HTTP/1.1\" 200 -\n",
      "127.0.0.1 - - [26/Jun/2018 15:44:57] \"GET /_dash-component-suites/dash_renderer/bundle.js?v=0.13.0 HTTP/1.1\" 200 -\n",
      "127.0.0.1 - - [26/Jun/2018 15:44:58] \"GET /_dash-layout HTTP/1.1\" 200 -\n",
      "127.0.0.1 - - [26/Jun/2018 15:44:58] \"GET /_dash-dependencies HTTP/1.1\" 200 -\n",
      "[2018-06-26 15:44:58,437] ERROR in app: Exception on /_dash-update-component [POST]\n",
      "Traceback (most recent call last):\n",
      "  File \"/usr/local/lib/python3.5/dist-packages/flask/app.py\", line 1982, in wsgi_app\n",
      "    response = self.full_dispatch_request()\n",
      "  File \"/usr/local/lib/python3.5/dist-packages/flask/app.py\", line 1614, in full_dispatch_request\n",
      "    rv = self.handle_user_exception(e)\n",
      "  File \"/usr/local/lib/python3.5/dist-packages/flask/app.py\", line 1517, in handle_user_exception\n",
      "    reraise(exc_type, exc_value, tb)\n",
      "  File \"/usr/local/lib/python3.5/dist-packages/flask/_compat.py\", line 33, in reraise\n",
      "    raise value\n",
      "  File \"/usr/local/lib/python3.5/dist-packages/flask/app.py\", line 1612, in full_dispatch_request\n",
      "    rv = self.dispatch_request()\n",
      "  File \"/usr/local/lib/python3.5/dist-packages/flask/app.py\", line 1598, in dispatch_request\n",
      "    return self.view_functions[rule.endpoint](**req.view_args)\n",
      "  File \"/usr/local/lib/python3.5/dist-packages/dash/dash.py\", line 558, in dispatch\n",
      "    return self.callback_map[target_id]['callback'](*args)\n",
      "  File \"/usr/local/lib/python3.5/dist-packages/dash/dash.py\", line 515, in add_context\n",
      "    output_value = func(*args, **kwargs)\n",
      "  File \"<ipython-input-24-45bfb2ec72c7>\", line 129, in gen_loss\n",
      "    x=get_xs(),\n",
      "NameError: name 'get_xs' is not defined\n",
      "127.0.0.1 - - [26/Jun/2018 15:44:58] \"POST /_dash-update-component HTTP/1.1\" 500 -\n",
      "[2018-06-26 15:44:58,450] ERROR in app: Exception on /_dash-update-component [POST]\n",
      "Traceback (most recent call last):\n",
      "  File \"/usr/local/lib/python3.5/dist-packages/flask/app.py\", line 1982, in wsgi_app\n",
      "    response = self.full_dispatch_request()\n",
      "  File \"/usr/local/lib/python3.5/dist-packages/flask/app.py\", line 1614, in full_dispatch_request\n",
      "    rv = self.handle_user_exception(e)\n",
      "  File \"/usr/local/lib/python3.5/dist-packages/flask/app.py\", line 1517, in handle_user_exception\n",
      "    reraise(exc_type, exc_value, tb)\n",
      "  File \"/usr/local/lib/python3.5/dist-packages/flask/_compat.py\", line 33, in reraise\n",
      "    raise value\n",
      "  File \"/usr/local/lib/python3.5/dist-packages/flask/app.py\", line 1612, in full_dispatch_request\n",
      "    rv = self.dispatch_request()\n",
      "  File \"/usr/local/lib/python3.5/dist-packages/flask/app.py\", line 1598, in dispatch_request\n",
      "    return self.view_functions[rule.endpoint](**req.view_args)\n",
      "  File \"/usr/local/lib/python3.5/dist-packages/dash/dash.py\", line 558, in dispatch\n",
      "    return self.callback_map[target_id]['callback'](*args)\n",
      "  File \"/usr/local/lib/python3.5/dist-packages/dash/dash.py\", line 515, in add_context\n",
      "    output_value = func(*args, **kwargs)\n",
      "  File \"<ipython-input-24-45bfb2ec72c7>\", line 198, in update_output\n",
      "    v = json.loads(value)\n",
      "  File \"/usr/lib/python3.5/json/__init__.py\", line 312, in loads\n",
      "    s.__class__.__name__))\n",
      "TypeError: the JSON object must be str, not 'NoneType'\n",
      "127.0.0.1 - - [26/Jun/2018 15:44:58] \"POST /_dash-update-component HTTP/1.1\" 500 -\n",
      "127.0.0.1 - - [26/Jun/2018 15:44:58] \"POST /_dash-update-component HTTP/1.1\" 200 -\n",
      "[2018-06-26 15:44:58,461] ERROR in app: Exception on /_dash-update-component [POST]\n",
      "Traceback (most recent call last):\n",
      "  File \"/usr/local/lib/python3.5/dist-packages/flask/app.py\", line 1982, in wsgi_app\n",
      "    response = self.full_dispatch_request()\n",
      "  File \"/usr/local/lib/python3.5/dist-packages/flask/app.py\", line 1614, in full_dispatch_request\n",
      "    rv = self.handle_user_exception(e)\n",
      "  File \"/usr/local/lib/python3.5/dist-packages/flask/app.py\", line 1517, in handle_user_exception\n",
      "    reraise(exc_type, exc_value, tb)\n",
      "  File \"/usr/local/lib/python3.5/dist-packages/flask/_compat.py\", line 33, in reraise\n",
      "    raise value\n",
      "  File \"/usr/local/lib/python3.5/dist-packages/flask/app.py\", line 1612, in full_dispatch_request\n",
      "    rv = self.dispatch_request()\n",
      "  File \"/usr/local/lib/python3.5/dist-packages/flask/app.py\", line 1598, in dispatch_request\n",
      "    return self.view_functions[rule.endpoint](**req.view_args)\n",
      "  File \"/usr/local/lib/python3.5/dist-packages/dash/dash.py\", line 558, in dispatch\n",
      "    return self.callback_map[target_id]['callback'](*args)\n",
      "  File \"/usr/local/lib/python3.5/dist-packages/dash/dash.py\", line 515, in add_context\n",
      "    output_value = func(*args, **kwargs)\n",
      "  File \"<ipython-input-24-45bfb2ec72c7>\", line 115, in gen_cost\n",
      "    child = \"Test data: %f\" % get_cost()\n",
      "  File \"<ipython-input-24-45bfb2ec72c7>\", line 108, in get_cost\n",
      "    cost += random.random()\n",
      "NameError: name 'random' is not defined\n",
      "127.0.0.1 - - [26/Jun/2018 15:44:58] \"POST /_dash-update-component HTTP/1.1\" 500 -\n",
      "[2018-06-26 15:45:00,214] ERROR in app: Exception on /_dash-update-component [POST]\n",
      "Traceback (most recent call last):\n",
      "  File \"/usr/local/lib/python3.5/dist-packages/flask/app.py\", line 1982, in wsgi_app\n",
      "    response = self.full_dispatch_request()\n",
      "  File \"/usr/local/lib/python3.5/dist-packages/flask/app.py\", line 1614, in full_dispatch_request\n",
      "    rv = self.handle_user_exception(e)\n",
      "  File \"/usr/local/lib/python3.5/dist-packages/flask/app.py\", line 1517, in handle_user_exception\n",
      "    reraise(exc_type, exc_value, tb)\n",
      "  File \"/usr/local/lib/python3.5/dist-packages/flask/_compat.py\", line 33, in reraise\n",
      "    raise value\n",
      "  File \"/usr/local/lib/python3.5/dist-packages/flask/app.py\", line 1612, in full_dispatch_request\n",
      "    rv = self.dispatch_request()\n",
      "  File \"/usr/local/lib/python3.5/dist-packages/flask/app.py\", line 1598, in dispatch_request\n",
      "    return self.view_functions[rule.endpoint](**req.view_args)\n",
      "  File \"/usr/local/lib/python3.5/dist-packages/dash/dash.py\", line 558, in dispatch\n",
      "    return self.callback_map[target_id]['callback'](*args)\n",
      "  File \"/usr/local/lib/python3.5/dist-packages/dash/dash.py\", line 515, in add_context\n",
      "    output_value = func(*args, **kwargs)\n",
      "  File \"<ipython-input-24-45bfb2ec72c7>\", line 115, in gen_cost\n",
      "    child = \"Test data: %f\" % get_cost()\n",
      "  File \"<ipython-input-24-45bfb2ec72c7>\", line 108, in get_cost\n",
      "    cost += random.random()\n",
      "NameError: name 'random' is not defined\n",
      "127.0.0.1 - - [26/Jun/2018 15:45:00] \"POST /_dash-update-component HTTP/1.1\" 500 -\n",
      "[2018-06-26 15:45:00,236] ERROR in app: Exception on /_dash-update-component [POST]\n",
      "Traceback (most recent call last):\n",
      "  File \"/usr/local/lib/python3.5/dist-packages/flask/app.py\", line 1982, in wsgi_app\n",
      "    response = self.full_dispatch_request()\n",
      "  File \"/usr/local/lib/python3.5/dist-packages/flask/app.py\", line 1614, in full_dispatch_request\n",
      "    rv = self.handle_user_exception(e)\n",
      "  File \"/usr/local/lib/python3.5/dist-packages/flask/app.py\", line 1517, in handle_user_exception\n",
      "    reraise(exc_type, exc_value, tb)\n",
      "  File \"/usr/local/lib/python3.5/dist-packages/flask/_compat.py\", line 33, in reraise\n",
      "    raise value\n",
      "  File \"/usr/local/lib/python3.5/dist-packages/flask/app.py\", line 1612, in full_dispatch_request\n",
      "    rv = self.dispatch_request()\n",
      "  File \"/usr/local/lib/python3.5/dist-packages/flask/app.py\", line 1598, in dispatch_request\n",
      "    return self.view_functions[rule.endpoint](**req.view_args)\n",
      "  File \"/usr/local/lib/python3.5/dist-packages/dash/dash.py\", line 558, in dispatch\n",
      "    return self.callback_map[target_id]['callback'](*args)\n",
      "  File \"/usr/local/lib/python3.5/dist-packages/dash/dash.py\", line 515, in add_context\n",
      "    output_value = func(*args, **kwargs)\n",
      "  File \"<ipython-input-24-45bfb2ec72c7>\", line 129, in gen_loss\n",
      "    x=get_xs(),\n",
      "NameError: name 'get_xs' is not defined\n"
     ]
    },
    {
     "name": "stderr",
     "output_type": "stream",
     "text": [
      "127.0.0.1 - - [26/Jun/2018 15:45:00] \"POST /_dash-update-component HTTP/1.1\" 500 -\n",
      "[2018-06-26 15:45:01,554] ERROR in app: Exception on /_dash-update-component [POST]\n",
      "Traceback (most recent call last):\n",
      "  File \"/usr/local/lib/python3.5/dist-packages/flask/app.py\", line 1982, in wsgi_app\n",
      "    response = self.full_dispatch_request()\n",
      "  File \"/usr/local/lib/python3.5/dist-packages/flask/app.py\", line 1614, in full_dispatch_request\n",
      "    rv = self.handle_user_exception(e)\n",
      "  File \"/usr/local/lib/python3.5/dist-packages/flask/app.py\", line 1517, in handle_user_exception\n",
      "    reraise(exc_type, exc_value, tb)\n",
      "  File \"/usr/local/lib/python3.5/dist-packages/flask/_compat.py\", line 33, in reraise\n",
      "    raise value\n",
      "  File \"/usr/local/lib/python3.5/dist-packages/flask/app.py\", line 1612, in full_dispatch_request\n",
      "    rv = self.dispatch_request()\n",
      "  File \"/usr/local/lib/python3.5/dist-packages/flask/app.py\", line 1598, in dispatch_request\n",
      "    return self.view_functions[rule.endpoint](**req.view_args)\n",
      "  File \"/usr/local/lib/python3.5/dist-packages/dash/dash.py\", line 558, in dispatch\n",
      "    return self.callback_map[target_id]['callback'](*args)\n",
      "  File \"/usr/local/lib/python3.5/dist-packages/dash/dash.py\", line 515, in add_context\n",
      "    output_value = func(*args, **kwargs)\n",
      "  File \"<ipython-input-24-45bfb2ec72c7>\", line 129, in gen_loss\n",
      "    x=get_xs(),\n",
      "NameError: name 'get_xs' is not defined\n",
      "127.0.0.1 - - [26/Jun/2018 15:45:01] \"POST /_dash-update-component HTTP/1.1\" 500 -\n",
      "[2018-06-26 15:45:01,559] ERROR in app: Exception on /_dash-update-component [POST]\n",
      "Traceback (most recent call last):\n",
      "  File \"/usr/local/lib/python3.5/dist-packages/flask/app.py\", line 1982, in wsgi_app\n",
      "    response = self.full_dispatch_request()\n",
      "  File \"/usr/local/lib/python3.5/dist-packages/flask/app.py\", line 1614, in full_dispatch_request\n",
      "    rv = self.handle_user_exception(e)\n",
      "  File \"/usr/local/lib/python3.5/dist-packages/flask/app.py\", line 1517, in handle_user_exception\n",
      "    reraise(exc_type, exc_value, tb)\n",
      "  File \"/usr/local/lib/python3.5/dist-packages/flask/_compat.py\", line 33, in reraise\n",
      "    raise value\n",
      "  File \"/usr/local/lib/python3.5/dist-packages/flask/app.py\", line 1612, in full_dispatch_request\n",
      "    rv = self.dispatch_request()\n",
      "  File \"/usr/local/lib/python3.5/dist-packages/flask/app.py\", line 1598, in dispatch_request\n",
      "    return self.view_functions[rule.endpoint](**req.view_args)\n",
      "  File \"/usr/local/lib/python3.5/dist-packages/dash/dash.py\", line 558, in dispatch\n",
      "    return self.callback_map[target_id]['callback'](*args)\n",
      "  File \"/usr/local/lib/python3.5/dist-packages/dash/dash.py\", line 515, in add_context\n",
      "    output_value = func(*args, **kwargs)\n",
      "  File \"<ipython-input-24-45bfb2ec72c7>\", line 115, in gen_cost\n",
      "    child = \"Test data: %f\" % get_cost()\n",
      "  File \"<ipython-input-24-45bfb2ec72c7>\", line 108, in get_cost\n",
      "    cost += random.random()\n",
      "NameError: name 'random' is not defined\n",
      "127.0.0.1 - - [26/Jun/2018 15:45:01] \"POST /_dash-update-component HTTP/1.1\" 500 -\n",
      "[2018-06-26 15:45:03,245] ERROR in app: Exception on /_dash-update-component [POST]\n",
      "Traceback (most recent call last):\n",
      "  File \"/usr/local/lib/python3.5/dist-packages/flask/app.py\", line 1982, in wsgi_app\n",
      "    response = self.full_dispatch_request()\n",
      "  File \"/usr/local/lib/python3.5/dist-packages/flask/app.py\", line 1614, in full_dispatch_request\n",
      "    rv = self.handle_user_exception(e)\n",
      "  File \"/usr/local/lib/python3.5/dist-packages/flask/app.py\", line 1517, in handle_user_exception\n",
      "    reraise(exc_type, exc_value, tb)\n",
      "  File \"/usr/local/lib/python3.5/dist-packages/flask/_compat.py\", line 33, in reraise\n",
      "    raise value\n",
      "  File \"/usr/local/lib/python3.5/dist-packages/flask/app.py\", line 1612, in full_dispatch_request\n",
      "    rv = self.dispatch_request()\n",
      "  File \"/usr/local/lib/python3.5/dist-packages/flask/app.py\", line 1598, in dispatch_request\n",
      "    return self.view_functions[rule.endpoint](**req.view_args)\n",
      "  File \"/usr/local/lib/python3.5/dist-packages/dash/dash.py\", line 558, in dispatch\n",
      "    return self.callback_map[target_id]['callback'](*args)\n",
      "  File \"/usr/local/lib/python3.5/dist-packages/dash/dash.py\", line 515, in add_context\n",
      "    output_value = func(*args, **kwargs)\n",
      "  File \"<ipython-input-24-45bfb2ec72c7>\", line 115, in gen_cost\n",
      "    child = \"Test data: %f\" % get_cost()\n",
      "  File \"<ipython-input-24-45bfb2ec72c7>\", line 108, in get_cost\n",
      "    cost += random.random()\n",
      "NameError: name 'random' is not defined\n",
      "127.0.0.1 - - [26/Jun/2018 15:45:03] \"POST /_dash-update-component HTTP/1.1\" 500 -\n",
      "[2018-06-26 15:45:03,258] ERROR in app: Exception on /_dash-update-component [POST]\n",
      "Traceback (most recent call last):\n",
      "  File \"/usr/local/lib/python3.5/dist-packages/flask/app.py\", line 1982, in wsgi_app\n",
      "    response = self.full_dispatch_request()\n",
      "  File \"/usr/local/lib/python3.5/dist-packages/flask/app.py\", line 1614, in full_dispatch_request\n",
      "    rv = self.handle_user_exception(e)\n",
      "  File \"/usr/local/lib/python3.5/dist-packages/flask/app.py\", line 1517, in handle_user_exception\n",
      "    reraise(exc_type, exc_value, tb)\n",
      "  File \"/usr/local/lib/python3.5/dist-packages/flask/_compat.py\", line 33, in reraise\n",
      "    raise value\n",
      "  File \"/usr/local/lib/python3.5/dist-packages/flask/app.py\", line 1612, in full_dispatch_request\n",
      "    rv = self.dispatch_request()\n",
      "  File \"/usr/local/lib/python3.5/dist-packages/flask/app.py\", line 1598, in dispatch_request\n",
      "    return self.view_functions[rule.endpoint](**req.view_args)\n",
      "  File \"/usr/local/lib/python3.5/dist-packages/dash/dash.py\", line 558, in dispatch\n",
      "    return self.callback_map[target_id]['callback'](*args)\n",
      "  File \"/usr/local/lib/python3.5/dist-packages/dash/dash.py\", line 515, in add_context\n",
      "    output_value = func(*args, **kwargs)\n",
      "  File \"<ipython-input-24-45bfb2ec72c7>\", line 129, in gen_loss\n",
      "    x=get_xs(),\n",
      "NameError: name 'get_xs' is not defined\n",
      "127.0.0.1 - - [26/Jun/2018 15:45:03] \"POST /_dash-update-component HTTP/1.1\" 500 -\n",
      "[2018-06-26 15:45:04,572] ERROR in app: Exception on /_dash-update-component [POST]\n",
      "Traceback (most recent call last):\n",
      "  File \"/usr/local/lib/python3.5/dist-packages/flask/app.py\", line 1982, in wsgi_app\n",
      "    response = self.full_dispatch_request()\n",
      "  File \"/usr/local/lib/python3.5/dist-packages/flask/app.py\", line 1614, in full_dispatch_request\n",
      "    rv = self.handle_user_exception(e)\n",
      "  File \"/usr/local/lib/python3.5/dist-packages/flask/app.py\", line 1517, in handle_user_exception\n",
      "    reraise(exc_type, exc_value, tb)\n",
      "  File \"/usr/local/lib/python3.5/dist-packages/flask/_compat.py\", line 33, in reraise\n",
      "    raise value\n",
      "  File \"/usr/local/lib/python3.5/dist-packages/flask/app.py\", line 1612, in full_dispatch_request\n",
      "    rv = self.dispatch_request()\n",
      "  File \"/usr/local/lib/python3.5/dist-packages/flask/app.py\", line 1598, in dispatch_request\n",
      "    return self.view_functions[rule.endpoint](**req.view_args)\n",
      "  File \"/usr/local/lib/python3.5/dist-packages/dash/dash.py\", line 558, in dispatch\n",
      "    return self.callback_map[target_id]['callback'](*args)\n",
      "  File \"/usr/local/lib/python3.5/dist-packages/dash/dash.py\", line 515, in add_context\n",
      "    output_value = func(*args, **kwargs)\n",
      "  File \"<ipython-input-24-45bfb2ec72c7>\", line 129, in gen_loss\n",
      "    x=get_xs(),\n",
      "NameError: name 'get_xs' is not defined\n",
      "127.0.0.1 - - [26/Jun/2018 15:45:04] \"POST /_dash-update-component HTTP/1.1\" 500 -\n",
      "[2018-06-26 15:45:04,577] ERROR in app: Exception on /_dash-update-component [POST]\n",
      "Traceback (most recent call last):\n",
      "  File \"/usr/local/lib/python3.5/dist-packages/flask/app.py\", line 1982, in wsgi_app\n",
      "    response = self.full_dispatch_request()\n",
      "  File \"/usr/local/lib/python3.5/dist-packages/flask/app.py\", line 1614, in full_dispatch_request\n",
      "    rv = self.handle_user_exception(e)\n",
      "  File \"/usr/local/lib/python3.5/dist-packages/flask/app.py\", line 1517, in handle_user_exception\n",
      "    reraise(exc_type, exc_value, tb)\n",
      "  File \"/usr/local/lib/python3.5/dist-packages/flask/_compat.py\", line 33, in reraise\n",
      "    raise value\n",
      "  File \"/usr/local/lib/python3.5/dist-packages/flask/app.py\", line 1612, in full_dispatch_request\n",
      "    rv = self.dispatch_request()\n",
      "  File \"/usr/local/lib/python3.5/dist-packages/flask/app.py\", line 1598, in dispatch_request\n",
      "    return self.view_functions[rule.endpoint](**req.view_args)\n",
      "  File \"/usr/local/lib/python3.5/dist-packages/dash/dash.py\", line 558, in dispatch\n",
      "    return self.callback_map[target_id]['callback'](*args)\n",
      "  File \"/usr/local/lib/python3.5/dist-packages/dash/dash.py\", line 515, in add_context\n",
      "    output_value = func(*args, **kwargs)\n",
      "  File \"<ipython-input-24-45bfb2ec72c7>\", line 115, in gen_cost\n",
      "    child = \"Test data: %f\" % get_cost()\n",
      "  File \"<ipython-input-24-45bfb2ec72c7>\", line 108, in get_cost\n",
      "    cost += random.random()\n",
      "NameError: name 'random' is not defined\n"
     ]
    },
    {
     "name": "stderr",
     "output_type": "stream",
     "text": [
      "127.0.0.1 - - [26/Jun/2018 15:45:04] \"POST /_dash-update-component HTTP/1.1\" 500 -\n",
      "[2018-06-26 15:45:06,323] ERROR in app: Exception on /_dash-update-component [POST]\n",
      "Traceback (most recent call last):\n",
      "  File \"/usr/local/lib/python3.5/dist-packages/flask/app.py\", line 1982, in wsgi_app\n",
      "    response = self.full_dispatch_request()\n",
      "  File \"/usr/local/lib/python3.5/dist-packages/flask/app.py\", line 1614, in full_dispatch_request\n",
      "    rv = self.handle_user_exception(e)\n",
      "  File \"/usr/local/lib/python3.5/dist-packages/flask/app.py\", line 1517, in handle_user_exception\n",
      "    reraise(exc_type, exc_value, tb)\n",
      "  File \"/usr/local/lib/python3.5/dist-packages/flask/_compat.py\", line 33, in reraise\n",
      "    raise value\n",
      "  File \"/usr/local/lib/python3.5/dist-packages/flask/app.py\", line 1612, in full_dispatch_request\n",
      "    rv = self.dispatch_request()\n",
      "  File \"/usr/local/lib/python3.5/dist-packages/flask/app.py\", line 1598, in dispatch_request\n",
      "    return self.view_functions[rule.endpoint](**req.view_args)\n",
      "  File \"/usr/local/lib/python3.5/dist-packages/dash/dash.py\", line 558, in dispatch\n",
      "    return self.callback_map[target_id]['callback'](*args)\n",
      "  File \"/usr/local/lib/python3.5/dist-packages/dash/dash.py\", line 515, in add_context\n",
      "    output_value = func(*args, **kwargs)\n",
      "  File \"<ipython-input-24-45bfb2ec72c7>\", line 115, in gen_cost\n",
      "    child = \"Test data: %f\" % get_cost()\n",
      "  File \"<ipython-input-24-45bfb2ec72c7>\", line 108, in get_cost\n",
      "    cost += random.random()\n",
      "NameError: name 'random' is not defined\n",
      "127.0.0.1 - - [26/Jun/2018 15:45:06] \"POST /_dash-update-component HTTP/1.1\" 500 -\n",
      "[2018-06-26 15:45:06,336] ERROR in app: Exception on /_dash-update-component [POST]\n",
      "Traceback (most recent call last):\n",
      "  File \"/usr/local/lib/python3.5/dist-packages/flask/app.py\", line 1982, in wsgi_app\n",
      "    response = self.full_dispatch_request()\n",
      "  File \"/usr/local/lib/python3.5/dist-packages/flask/app.py\", line 1614, in full_dispatch_request\n",
      "    rv = self.handle_user_exception(e)\n",
      "  File \"/usr/local/lib/python3.5/dist-packages/flask/app.py\", line 1517, in handle_user_exception\n",
      "    reraise(exc_type, exc_value, tb)\n",
      "  File \"/usr/local/lib/python3.5/dist-packages/flask/_compat.py\", line 33, in reraise\n",
      "    raise value\n",
      "  File \"/usr/local/lib/python3.5/dist-packages/flask/app.py\", line 1612, in full_dispatch_request\n",
      "    rv = self.dispatch_request()\n",
      "  File \"/usr/local/lib/python3.5/dist-packages/flask/app.py\", line 1598, in dispatch_request\n",
      "    return self.view_functions[rule.endpoint](**req.view_args)\n",
      "  File \"/usr/local/lib/python3.5/dist-packages/dash/dash.py\", line 558, in dispatch\n",
      "    return self.callback_map[target_id]['callback'](*args)\n",
      "  File \"/usr/local/lib/python3.5/dist-packages/dash/dash.py\", line 515, in add_context\n",
      "    output_value = func(*args, **kwargs)\n",
      "  File \"<ipython-input-24-45bfb2ec72c7>\", line 129, in gen_loss\n",
      "    x=get_xs(),\n",
      "NameError: name 'get_xs' is not defined\n",
      "127.0.0.1 - - [26/Jun/2018 15:45:06] \"POST /_dash-update-component HTTP/1.1\" 500 -\n",
      "[2018-06-26 15:45:07,591] ERROR in app: Exception on /_dash-update-component [POST]\n",
      "Traceback (most recent call last):\n",
      "  File \"/usr/local/lib/python3.5/dist-packages/flask/app.py\", line 1982, in wsgi_app\n",
      "    response = self.full_dispatch_request()\n",
      "  File \"/usr/local/lib/python3.5/dist-packages/flask/app.py\", line 1614, in full_dispatch_request\n",
      "    rv = self.handle_user_exception(e)\n",
      "  File \"/usr/local/lib/python3.5/dist-packages/flask/app.py\", line 1517, in handle_user_exception\n",
      "    reraise(exc_type, exc_value, tb)\n",
      "  File \"/usr/local/lib/python3.5/dist-packages/flask/_compat.py\", line 33, in reraise\n",
      "    raise value\n",
      "  File \"/usr/local/lib/python3.5/dist-packages/flask/app.py\", line 1612, in full_dispatch_request\n",
      "    rv = self.dispatch_request()\n",
      "  File \"/usr/local/lib/python3.5/dist-packages/flask/app.py\", line 1598, in dispatch_request\n",
      "    return self.view_functions[rule.endpoint](**req.view_args)\n",
      "  File \"/usr/local/lib/python3.5/dist-packages/dash/dash.py\", line 558, in dispatch\n",
      "    return self.callback_map[target_id]['callback'](*args)\n",
      "  File \"/usr/local/lib/python3.5/dist-packages/dash/dash.py\", line 515, in add_context\n",
      "    output_value = func(*args, **kwargs)\n",
      "  File \"<ipython-input-24-45bfb2ec72c7>\", line 129, in gen_loss\n",
      "    x=get_xs(),\n",
      "NameError: name 'get_xs' is not defined\n",
      "127.0.0.1 - - [26/Jun/2018 15:45:07] \"POST /_dash-update-component HTTP/1.1\" 500 -\n",
      "[2018-06-26 15:45:07,600] ERROR in app: Exception on /_dash-update-component [POST]\n",
      "Traceback (most recent call last):\n",
      "  File \"/usr/local/lib/python3.5/dist-packages/flask/app.py\", line 1982, in wsgi_app\n",
      "    response = self.full_dispatch_request()\n",
      "  File \"/usr/local/lib/python3.5/dist-packages/flask/app.py\", line 1614, in full_dispatch_request\n",
      "    rv = self.handle_user_exception(e)\n",
      "  File \"/usr/local/lib/python3.5/dist-packages/flask/app.py\", line 1517, in handle_user_exception\n",
      "    reraise(exc_type, exc_value, tb)\n",
      "  File \"/usr/local/lib/python3.5/dist-packages/flask/_compat.py\", line 33, in reraise\n",
      "    raise value\n",
      "  File \"/usr/local/lib/python3.5/dist-packages/flask/app.py\", line 1612, in full_dispatch_request\n",
      "    rv = self.dispatch_request()\n",
      "  File \"/usr/local/lib/python3.5/dist-packages/flask/app.py\", line 1598, in dispatch_request\n",
      "    return self.view_functions[rule.endpoint](**req.view_args)\n",
      "  File \"/usr/local/lib/python3.5/dist-packages/dash/dash.py\", line 558, in dispatch\n",
      "    return self.callback_map[target_id]['callback'](*args)\n",
      "  File \"/usr/local/lib/python3.5/dist-packages/dash/dash.py\", line 515, in add_context\n",
      "    output_value = func(*args, **kwargs)\n",
      "  File \"<ipython-input-24-45bfb2ec72c7>\", line 115, in gen_cost\n",
      "    child = \"Test data: %f\" % get_cost()\n",
      "  File \"<ipython-input-24-45bfb2ec72c7>\", line 108, in get_cost\n",
      "    cost += random.random()\n",
      "NameError: name 'random' is not defined\n",
      "127.0.0.1 - - [26/Jun/2018 15:45:07] \"POST /_dash-update-component HTTP/1.1\" 500 -\n",
      "[2018-06-26 15:45:09,364] ERROR in app: Exception on /_dash-update-component [POST]\n",
      "Traceback (most recent call last):\n",
      "  File \"/usr/local/lib/python3.5/dist-packages/flask/app.py\", line 1982, in wsgi_app\n",
      "    response = self.full_dispatch_request()\n",
      "  File \"/usr/local/lib/python3.5/dist-packages/flask/app.py\", line 1614, in full_dispatch_request\n",
      "    rv = self.handle_user_exception(e)\n",
      "  File \"/usr/local/lib/python3.5/dist-packages/flask/app.py\", line 1517, in handle_user_exception\n",
      "    reraise(exc_type, exc_value, tb)\n",
      "  File \"/usr/local/lib/python3.5/dist-packages/flask/_compat.py\", line 33, in reraise\n",
      "    raise value\n",
      "  File \"/usr/local/lib/python3.5/dist-packages/flask/app.py\", line 1612, in full_dispatch_request\n",
      "    rv = self.dispatch_request()\n",
      "  File \"/usr/local/lib/python3.5/dist-packages/flask/app.py\", line 1598, in dispatch_request\n",
      "    return self.view_functions[rule.endpoint](**req.view_args)\n",
      "  File \"/usr/local/lib/python3.5/dist-packages/dash/dash.py\", line 558, in dispatch\n",
      "    return self.callback_map[target_id]['callback'](*args)\n",
      "  File \"/usr/local/lib/python3.5/dist-packages/dash/dash.py\", line 515, in add_context\n",
      "    output_value = func(*args, **kwargs)\n",
      "  File \"<ipython-input-24-45bfb2ec72c7>\", line 115, in gen_cost\n",
      "    child = \"Test data: %f\" % get_cost()\n",
      "  File \"<ipython-input-24-45bfb2ec72c7>\", line 108, in get_cost\n",
      "    cost += random.random()\n",
      "NameError: name 'random' is not defined\n",
      "127.0.0.1 - - [26/Jun/2018 15:45:09] \"POST /_dash-update-component HTTP/1.1\" 500 -\n",
      "[2018-06-26 15:45:09,385] ERROR in app: Exception on /_dash-update-component [POST]\n",
      "Traceback (most recent call last):\n",
      "  File \"/usr/local/lib/python3.5/dist-packages/flask/app.py\", line 1982, in wsgi_app\n",
      "    response = self.full_dispatch_request()\n",
      "  File \"/usr/local/lib/python3.5/dist-packages/flask/app.py\", line 1614, in full_dispatch_request\n",
      "    rv = self.handle_user_exception(e)\n",
      "  File \"/usr/local/lib/python3.5/dist-packages/flask/app.py\", line 1517, in handle_user_exception\n",
      "    reraise(exc_type, exc_value, tb)\n",
      "  File \"/usr/local/lib/python3.5/dist-packages/flask/_compat.py\", line 33, in reraise\n",
      "    raise value\n",
      "  File \"/usr/local/lib/python3.5/dist-packages/flask/app.py\", line 1612, in full_dispatch_request\n",
      "    rv = self.dispatch_request()\n",
      "  File \"/usr/local/lib/python3.5/dist-packages/flask/app.py\", line 1598, in dispatch_request\n",
      "    return self.view_functions[rule.endpoint](**req.view_args)\n",
      "  File \"/usr/local/lib/python3.5/dist-packages/dash/dash.py\", line 558, in dispatch\n",
      "    return self.callback_map[target_id]['callback'](*args)\n",
      "  File \"/usr/local/lib/python3.5/dist-packages/dash/dash.py\", line 515, in add_context\n",
      "    output_value = func(*args, **kwargs)\n",
      "  File \"<ipython-input-24-45bfb2ec72c7>\", line 129, in gen_loss\n",
      "    x=get_xs(),\n",
      "NameError: name 'get_xs' is not defined\n"
     ]
    },
    {
     "name": "stderr",
     "output_type": "stream",
     "text": [
      "127.0.0.1 - - [26/Jun/2018 15:45:09] \"POST /_dash-update-component HTTP/1.1\" 500 -\n",
      "[2018-06-26 15:45:10,553] ERROR in app: Exception on /_dash-update-component [POST]\n",
      "Traceback (most recent call last):\n",
      "  File \"/usr/local/lib/python3.5/dist-packages/flask/app.py\", line 1982, in wsgi_app\n",
      "    response = self.full_dispatch_request()\n",
      "  File \"/usr/local/lib/python3.5/dist-packages/flask/app.py\", line 1614, in full_dispatch_request\n",
      "    rv = self.handle_user_exception(e)\n",
      "  File \"/usr/local/lib/python3.5/dist-packages/flask/app.py\", line 1517, in handle_user_exception\n",
      "    reraise(exc_type, exc_value, tb)\n",
      "  File \"/usr/local/lib/python3.5/dist-packages/flask/_compat.py\", line 33, in reraise\n",
      "    raise value\n",
      "  File \"/usr/local/lib/python3.5/dist-packages/flask/app.py\", line 1612, in full_dispatch_request\n",
      "    rv = self.dispatch_request()\n",
      "  File \"/usr/local/lib/python3.5/dist-packages/flask/app.py\", line 1598, in dispatch_request\n",
      "    return self.view_functions[rule.endpoint](**req.view_args)\n",
      "  File \"/usr/local/lib/python3.5/dist-packages/dash/dash.py\", line 558, in dispatch\n",
      "    return self.callback_map[target_id]['callback'](*args)\n",
      "  File \"/usr/local/lib/python3.5/dist-packages/dash/dash.py\", line 515, in add_context\n",
      "    output_value = func(*args, **kwargs)\n",
      "  File \"<ipython-input-24-45bfb2ec72c7>\", line 129, in gen_loss\n",
      "    x=get_xs(),\n",
      "NameError: name 'get_xs' is not defined\n",
      "127.0.0.1 - - [26/Jun/2018 15:45:10] \"POST /_dash-update-component HTTP/1.1\" 500 -\n",
      "[2018-06-26 15:45:10,563] ERROR in app: Exception on /_dash-update-component [POST]\n",
      "Traceback (most recent call last):\n",
      "  File \"/usr/local/lib/python3.5/dist-packages/flask/app.py\", line 1982, in wsgi_app\n",
      "    response = self.full_dispatch_request()\n",
      "  File \"/usr/local/lib/python3.5/dist-packages/flask/app.py\", line 1614, in full_dispatch_request\n",
      "    rv = self.handle_user_exception(e)\n",
      "  File \"/usr/local/lib/python3.5/dist-packages/flask/app.py\", line 1517, in handle_user_exception\n",
      "    reraise(exc_type, exc_value, tb)\n",
      "  File \"/usr/local/lib/python3.5/dist-packages/flask/_compat.py\", line 33, in reraise\n",
      "    raise value\n",
      "  File \"/usr/local/lib/python3.5/dist-packages/flask/app.py\", line 1612, in full_dispatch_request\n",
      "    rv = self.dispatch_request()\n",
      "  File \"/usr/local/lib/python3.5/dist-packages/flask/app.py\", line 1598, in dispatch_request\n",
      "    return self.view_functions[rule.endpoint](**req.view_args)\n",
      "  File \"/usr/local/lib/python3.5/dist-packages/dash/dash.py\", line 558, in dispatch\n",
      "    return self.callback_map[target_id]['callback'](*args)\n",
      "  File \"/usr/local/lib/python3.5/dist-packages/dash/dash.py\", line 515, in add_context\n",
      "    output_value = func(*args, **kwargs)\n",
      "  File \"<ipython-input-24-45bfb2ec72c7>\", line 115, in gen_cost\n",
      "    child = \"Test data: %f\" % get_cost()\n",
      "  File \"<ipython-input-24-45bfb2ec72c7>\", line 108, in get_cost\n",
      "    cost += random.random()\n",
      "NameError: name 'random' is not defined\n",
      "127.0.0.1 - - [26/Jun/2018 15:45:10] \"POST /_dash-update-component HTTP/1.1\" 500 -\n",
      "[2018-06-26 15:45:12,399] ERROR in app: Exception on /_dash-update-component [POST]\n",
      "Traceback (most recent call last):\n",
      "  File \"/usr/local/lib/python3.5/dist-packages/flask/app.py\", line 1982, in wsgi_app\n",
      "    response = self.full_dispatch_request()\n",
      "  File \"/usr/local/lib/python3.5/dist-packages/flask/app.py\", line 1614, in full_dispatch_request\n",
      "    rv = self.handle_user_exception(e)\n",
      "  File \"/usr/local/lib/python3.5/dist-packages/flask/app.py\", line 1517, in handle_user_exception\n",
      "    reraise(exc_type, exc_value, tb)\n",
      "  File \"/usr/local/lib/python3.5/dist-packages/flask/_compat.py\", line 33, in reraise\n",
      "    raise value\n",
      "  File \"/usr/local/lib/python3.5/dist-packages/flask/app.py\", line 1612, in full_dispatch_request\n",
      "    rv = self.dispatch_request()\n",
      "  File \"/usr/local/lib/python3.5/dist-packages/flask/app.py\", line 1598, in dispatch_request\n",
      "    return self.view_functions[rule.endpoint](**req.view_args)\n",
      "  File \"/usr/local/lib/python3.5/dist-packages/dash/dash.py\", line 558, in dispatch\n",
      "    return self.callback_map[target_id]['callback'](*args)\n",
      "  File \"/usr/local/lib/python3.5/dist-packages/dash/dash.py\", line 515, in add_context\n",
      "    output_value = func(*args, **kwargs)\n",
      "  File \"<ipython-input-24-45bfb2ec72c7>\", line 115, in gen_cost\n",
      "    child = \"Test data: %f\" % get_cost()\n",
      "  File \"<ipython-input-24-45bfb2ec72c7>\", line 108, in get_cost\n",
      "    cost += random.random()\n",
      "NameError: name 'random' is not defined\n",
      "127.0.0.1 - - [26/Jun/2018 15:45:12] \"POST /_dash-update-component HTTP/1.1\" 500 -\n",
      "[2018-06-26 15:45:12,409] ERROR in app: Exception on /_dash-update-component [POST]\n",
      "Traceback (most recent call last):\n",
      "  File \"/usr/local/lib/python3.5/dist-packages/flask/app.py\", line 1982, in wsgi_app\n",
      "    response = self.full_dispatch_request()\n",
      "  File \"/usr/local/lib/python3.5/dist-packages/flask/app.py\", line 1614, in full_dispatch_request\n",
      "    rv = self.handle_user_exception(e)\n",
      "  File \"/usr/local/lib/python3.5/dist-packages/flask/app.py\", line 1517, in handle_user_exception\n",
      "    reraise(exc_type, exc_value, tb)\n",
      "  File \"/usr/local/lib/python3.5/dist-packages/flask/_compat.py\", line 33, in reraise\n",
      "    raise value\n",
      "  File \"/usr/local/lib/python3.5/dist-packages/flask/app.py\", line 1612, in full_dispatch_request\n",
      "    rv = self.dispatch_request()\n",
      "  File \"/usr/local/lib/python3.5/dist-packages/flask/app.py\", line 1598, in dispatch_request\n",
      "    return self.view_functions[rule.endpoint](**req.view_args)\n",
      "  File \"/usr/local/lib/python3.5/dist-packages/dash/dash.py\", line 558, in dispatch\n",
      "    return self.callback_map[target_id]['callback'](*args)\n",
      "  File \"/usr/local/lib/python3.5/dist-packages/dash/dash.py\", line 515, in add_context\n",
      "    output_value = func(*args, **kwargs)\n",
      "  File \"<ipython-input-24-45bfb2ec72c7>\", line 129, in gen_loss\n",
      "    x=get_xs(),\n",
      "NameError: name 'get_xs' is not defined\n",
      "127.0.0.1 - - [26/Jun/2018 15:45:12] \"POST /_dash-update-component HTTP/1.1\" 500 -\n",
      "[2018-06-26 15:45:13,569] ERROR in app: Exception on /_dash-update-component [POST]\n",
      "Traceback (most recent call last):\n",
      "  File \"/usr/local/lib/python3.5/dist-packages/flask/app.py\", line 1982, in wsgi_app\n",
      "    response = self.full_dispatch_request()\n",
      "  File \"/usr/local/lib/python3.5/dist-packages/flask/app.py\", line 1614, in full_dispatch_request\n",
      "    rv = self.handle_user_exception(e)\n",
      "  File \"/usr/local/lib/python3.5/dist-packages/flask/app.py\", line 1517, in handle_user_exception\n",
      "    reraise(exc_type, exc_value, tb)\n",
      "  File \"/usr/local/lib/python3.5/dist-packages/flask/_compat.py\", line 33, in reraise\n",
      "    raise value\n",
      "  File \"/usr/local/lib/python3.5/dist-packages/flask/app.py\", line 1612, in full_dispatch_request\n",
      "    rv = self.dispatch_request()\n",
      "  File \"/usr/local/lib/python3.5/dist-packages/flask/app.py\", line 1598, in dispatch_request\n",
      "    return self.view_functions[rule.endpoint](**req.view_args)\n",
      "  File \"/usr/local/lib/python3.5/dist-packages/dash/dash.py\", line 558, in dispatch\n",
      "    return self.callback_map[target_id]['callback'](*args)\n",
      "  File \"/usr/local/lib/python3.5/dist-packages/dash/dash.py\", line 515, in add_context\n",
      "    output_value = func(*args, **kwargs)\n",
      "  File \"<ipython-input-24-45bfb2ec72c7>\", line 129, in gen_loss\n",
      "    x=get_xs(),\n",
      "NameError: name 'get_xs' is not defined\n",
      "127.0.0.1 - - [26/Jun/2018 15:45:13] \"POST /_dash-update-component HTTP/1.1\" 500 -\n",
      "[2018-06-26 15:45:13,579] ERROR in app: Exception on /_dash-update-component [POST]\n",
      "Traceback (most recent call last):\n",
      "  File \"/usr/local/lib/python3.5/dist-packages/flask/app.py\", line 1982, in wsgi_app\n",
      "    response = self.full_dispatch_request()\n",
      "  File \"/usr/local/lib/python3.5/dist-packages/flask/app.py\", line 1614, in full_dispatch_request\n",
      "    rv = self.handle_user_exception(e)\n",
      "  File \"/usr/local/lib/python3.5/dist-packages/flask/app.py\", line 1517, in handle_user_exception\n",
      "    reraise(exc_type, exc_value, tb)\n",
      "  File \"/usr/local/lib/python3.5/dist-packages/flask/_compat.py\", line 33, in reraise\n",
      "    raise value\n",
      "  File \"/usr/local/lib/python3.5/dist-packages/flask/app.py\", line 1612, in full_dispatch_request\n",
      "    rv = self.dispatch_request()\n",
      "  File \"/usr/local/lib/python3.5/dist-packages/flask/app.py\", line 1598, in dispatch_request\n",
      "    return self.view_functions[rule.endpoint](**req.view_args)\n",
      "  File \"/usr/local/lib/python3.5/dist-packages/dash/dash.py\", line 558, in dispatch\n",
      "    return self.callback_map[target_id]['callback'](*args)\n",
      "  File \"/usr/local/lib/python3.5/dist-packages/dash/dash.py\", line 515, in add_context\n",
      "    output_value = func(*args, **kwargs)\n",
      "  File \"<ipython-input-24-45bfb2ec72c7>\", line 115, in gen_cost\n",
      "    child = \"Test data: %f\" % get_cost()\n",
      "  File \"<ipython-input-24-45bfb2ec72c7>\", line 108, in get_cost\n",
      "    cost += random.random()\n",
      "NameError: name 'random' is not defined\n"
     ]
    },
    {
     "name": "stderr",
     "output_type": "stream",
     "text": [
      "127.0.0.1 - - [26/Jun/2018 15:45:13] \"POST /_dash-update-component HTTP/1.1\" 500 -\n",
      "[2018-06-26 15:45:15,453] ERROR in app: Exception on /_dash-update-component [POST]\n",
      "Traceback (most recent call last):\n",
      "  File \"/usr/local/lib/python3.5/dist-packages/flask/app.py\", line 1982, in wsgi_app\n",
      "    response = self.full_dispatch_request()\n",
      "  File \"/usr/local/lib/python3.5/dist-packages/flask/app.py\", line 1614, in full_dispatch_request\n",
      "    rv = self.handle_user_exception(e)\n",
      "  File \"/usr/local/lib/python3.5/dist-packages/flask/app.py\", line 1517, in handle_user_exception\n",
      "    reraise(exc_type, exc_value, tb)\n",
      "  File \"/usr/local/lib/python3.5/dist-packages/flask/_compat.py\", line 33, in reraise\n",
      "    raise value\n",
      "  File \"/usr/local/lib/python3.5/dist-packages/flask/app.py\", line 1612, in full_dispatch_request\n",
      "    rv = self.dispatch_request()\n",
      "  File \"/usr/local/lib/python3.5/dist-packages/flask/app.py\", line 1598, in dispatch_request\n",
      "    return self.view_functions[rule.endpoint](**req.view_args)\n",
      "  File \"/usr/local/lib/python3.5/dist-packages/dash/dash.py\", line 558, in dispatch\n",
      "    return self.callback_map[target_id]['callback'](*args)\n",
      "  File \"/usr/local/lib/python3.5/dist-packages/dash/dash.py\", line 515, in add_context\n",
      "    output_value = func(*args, **kwargs)\n",
      "  File \"<ipython-input-24-45bfb2ec72c7>\", line 115, in gen_cost\n",
      "    child = \"Test data: %f\" % get_cost()\n",
      "  File \"<ipython-input-24-45bfb2ec72c7>\", line 108, in get_cost\n",
      "    cost += random.random()\n",
      "NameError: name 'random' is not defined\n",
      "127.0.0.1 - - [26/Jun/2018 15:45:15] \"POST /_dash-update-component HTTP/1.1\" 500 -\n",
      "[2018-06-26 15:45:15,463] ERROR in app: Exception on /_dash-update-component [POST]\n",
      "Traceback (most recent call last):\n",
      "  File \"/usr/local/lib/python3.5/dist-packages/flask/app.py\", line 1982, in wsgi_app\n",
      "    response = self.full_dispatch_request()\n",
      "  File \"/usr/local/lib/python3.5/dist-packages/flask/app.py\", line 1614, in full_dispatch_request\n",
      "    rv = self.handle_user_exception(e)\n",
      "  File \"/usr/local/lib/python3.5/dist-packages/flask/app.py\", line 1517, in handle_user_exception\n",
      "    reraise(exc_type, exc_value, tb)\n",
      "  File \"/usr/local/lib/python3.5/dist-packages/flask/_compat.py\", line 33, in reraise\n",
      "    raise value\n",
      "  File \"/usr/local/lib/python3.5/dist-packages/flask/app.py\", line 1612, in full_dispatch_request\n",
      "    rv = self.dispatch_request()\n",
      "  File \"/usr/local/lib/python3.5/dist-packages/flask/app.py\", line 1598, in dispatch_request\n",
      "    return self.view_functions[rule.endpoint](**req.view_args)\n",
      "  File \"/usr/local/lib/python3.5/dist-packages/dash/dash.py\", line 558, in dispatch\n",
      "    return self.callback_map[target_id]['callback'](*args)\n",
      "  File \"/usr/local/lib/python3.5/dist-packages/dash/dash.py\", line 515, in add_context\n",
      "    output_value = func(*args, **kwargs)\n",
      "  File \"<ipython-input-24-45bfb2ec72c7>\", line 129, in gen_loss\n",
      "    x=get_xs(),\n",
      "NameError: name 'get_xs' is not defined\n",
      "127.0.0.1 - - [26/Jun/2018 15:45:15] \"POST /_dash-update-component HTTP/1.1\" 500 -\n",
      "[2018-06-26 15:45:16,550] ERROR in app: Exception on /_dash-update-component [POST]\n",
      "Traceback (most recent call last):\n",
      "  File \"/usr/local/lib/python3.5/dist-packages/flask/app.py\", line 1982, in wsgi_app\n",
      "    response = self.full_dispatch_request()\n",
      "  File \"/usr/local/lib/python3.5/dist-packages/flask/app.py\", line 1614, in full_dispatch_request\n",
      "    rv = self.handle_user_exception(e)\n",
      "  File \"/usr/local/lib/python3.5/dist-packages/flask/app.py\", line 1517, in handle_user_exception\n",
      "    reraise(exc_type, exc_value, tb)\n",
      "  File \"/usr/local/lib/python3.5/dist-packages/flask/_compat.py\", line 33, in reraise\n",
      "    raise value\n",
      "  File \"/usr/local/lib/python3.5/dist-packages/flask/app.py\", line 1612, in full_dispatch_request\n",
      "    rv = self.dispatch_request()\n",
      "  File \"/usr/local/lib/python3.5/dist-packages/flask/app.py\", line 1598, in dispatch_request\n",
      "    return self.view_functions[rule.endpoint](**req.view_args)\n",
      "  File \"/usr/local/lib/python3.5/dist-packages/dash/dash.py\", line 558, in dispatch\n",
      "    return self.callback_map[target_id]['callback'](*args)\n",
      "  File \"/usr/local/lib/python3.5/dist-packages/dash/dash.py\", line 515, in add_context\n",
      "    output_value = func(*args, **kwargs)\n",
      "  File \"<ipython-input-24-45bfb2ec72c7>\", line 129, in gen_loss\n",
      "    x=get_xs(),\n",
      "NameError: name 'get_xs' is not defined\n",
      "127.0.0.1 - - [26/Jun/2018 15:45:16] \"POST /_dash-update-component HTTP/1.1\" 500 -\n",
      "[2018-06-26 15:45:16,564] ERROR in app: Exception on /_dash-update-component [POST]\n",
      "Traceback (most recent call last):\n",
      "  File \"/usr/local/lib/python3.5/dist-packages/flask/app.py\", line 1982, in wsgi_app\n",
      "    response = self.full_dispatch_request()\n",
      "  File \"/usr/local/lib/python3.5/dist-packages/flask/app.py\", line 1614, in full_dispatch_request\n",
      "    rv = self.handle_user_exception(e)\n",
      "  File \"/usr/local/lib/python3.5/dist-packages/flask/app.py\", line 1517, in handle_user_exception\n",
      "    reraise(exc_type, exc_value, tb)\n",
      "  File \"/usr/local/lib/python3.5/dist-packages/flask/_compat.py\", line 33, in reraise\n",
      "    raise value\n",
      "  File \"/usr/local/lib/python3.5/dist-packages/flask/app.py\", line 1612, in full_dispatch_request\n",
      "    rv = self.dispatch_request()\n",
      "  File \"/usr/local/lib/python3.5/dist-packages/flask/app.py\", line 1598, in dispatch_request\n",
      "    return self.view_functions[rule.endpoint](**req.view_args)\n",
      "  File \"/usr/local/lib/python3.5/dist-packages/dash/dash.py\", line 558, in dispatch\n",
      "    return self.callback_map[target_id]['callback'](*args)\n",
      "  File \"/usr/local/lib/python3.5/dist-packages/dash/dash.py\", line 515, in add_context\n",
      "    output_value = func(*args, **kwargs)\n",
      "  File \"<ipython-input-24-45bfb2ec72c7>\", line 115, in gen_cost\n",
      "    child = \"Test data: %f\" % get_cost()\n",
      "  File \"<ipython-input-24-45bfb2ec72c7>\", line 108, in get_cost\n",
      "    cost += random.random()\n",
      "NameError: name 'random' is not defined\n",
      "127.0.0.1 - - [26/Jun/2018 15:45:16] \"POST /_dash-update-component HTTP/1.1\" 500 -\n",
      "[2018-06-26 15:45:18,526] ERROR in app: Exception on /_dash-update-component [POST]\n",
      "Traceback (most recent call last):\n",
      "  File \"/usr/local/lib/python3.5/dist-packages/flask/app.py\", line 1982, in wsgi_app\n",
      "    response = self.full_dispatch_request()\n",
      "  File \"/usr/local/lib/python3.5/dist-packages/flask/app.py\", line 1614, in full_dispatch_request\n",
      "    rv = self.handle_user_exception(e)\n",
      "  File \"/usr/local/lib/python3.5/dist-packages/flask/app.py\", line 1517, in handle_user_exception\n",
      "    reraise(exc_type, exc_value, tb)\n",
      "  File \"/usr/local/lib/python3.5/dist-packages/flask/_compat.py\", line 33, in reraise\n",
      "    raise value\n",
      "  File \"/usr/local/lib/python3.5/dist-packages/flask/app.py\", line 1612, in full_dispatch_request\n",
      "    rv = self.dispatch_request()\n",
      "  File \"/usr/local/lib/python3.5/dist-packages/flask/app.py\", line 1598, in dispatch_request\n",
      "    return self.view_functions[rule.endpoint](**req.view_args)\n",
      "  File \"/usr/local/lib/python3.5/dist-packages/dash/dash.py\", line 558, in dispatch\n",
      "    return self.callback_map[target_id]['callback'](*args)\n",
      "  File \"/usr/local/lib/python3.5/dist-packages/dash/dash.py\", line 515, in add_context\n",
      "    output_value = func(*args, **kwargs)\n",
      "  File \"<ipython-input-24-45bfb2ec72c7>\", line 115, in gen_cost\n",
      "    child = \"Test data: %f\" % get_cost()\n",
      "  File \"<ipython-input-24-45bfb2ec72c7>\", line 108, in get_cost\n",
      "    cost += random.random()\n",
      "NameError: name 'random' is not defined\n",
      "127.0.0.1 - - [26/Jun/2018 15:45:18] \"POST /_dash-update-component HTTP/1.1\" 500 -\n",
      "[2018-06-26 15:45:18,536] ERROR in app: Exception on /_dash-update-component [POST]\n",
      "Traceback (most recent call last):\n",
      "  File \"/usr/local/lib/python3.5/dist-packages/flask/app.py\", line 1982, in wsgi_app\n",
      "    response = self.full_dispatch_request()\n",
      "  File \"/usr/local/lib/python3.5/dist-packages/flask/app.py\", line 1614, in full_dispatch_request\n",
      "    rv = self.handle_user_exception(e)\n",
      "  File \"/usr/local/lib/python3.5/dist-packages/flask/app.py\", line 1517, in handle_user_exception\n",
      "    reraise(exc_type, exc_value, tb)\n",
      "  File \"/usr/local/lib/python3.5/dist-packages/flask/_compat.py\", line 33, in reraise\n",
      "    raise value\n",
      "  File \"/usr/local/lib/python3.5/dist-packages/flask/app.py\", line 1612, in full_dispatch_request\n",
      "    rv = self.dispatch_request()\n",
      "  File \"/usr/local/lib/python3.5/dist-packages/flask/app.py\", line 1598, in dispatch_request\n",
      "    return self.view_functions[rule.endpoint](**req.view_args)\n",
      "  File \"/usr/local/lib/python3.5/dist-packages/dash/dash.py\", line 558, in dispatch\n",
      "    return self.callback_map[target_id]['callback'](*args)\n",
      "  File \"/usr/local/lib/python3.5/dist-packages/dash/dash.py\", line 515, in add_context\n",
      "    output_value = func(*args, **kwargs)\n",
      "  File \"<ipython-input-24-45bfb2ec72c7>\", line 129, in gen_loss\n",
      "    x=get_xs(),\n",
      "NameError: name 'get_xs' is not defined\n"
     ]
    },
    {
     "name": "stderr",
     "output_type": "stream",
     "text": [
      "127.0.0.1 - - [26/Jun/2018 15:45:18] \"POST /_dash-update-component HTTP/1.1\" 500 -\n",
      "[2018-06-26 15:45:19,591] ERROR in app: Exception on /_dash-update-component [POST]\n",
      "Traceback (most recent call last):\n",
      "  File \"/usr/local/lib/python3.5/dist-packages/flask/app.py\", line 1982, in wsgi_app\n",
      "    response = self.full_dispatch_request()\n",
      "  File \"/usr/local/lib/python3.5/dist-packages/flask/app.py\", line 1614, in full_dispatch_request\n",
      "    rv = self.handle_user_exception(e)\n",
      "  File \"/usr/local/lib/python3.5/dist-packages/flask/app.py\", line 1517, in handle_user_exception\n",
      "    reraise(exc_type, exc_value, tb)\n",
      "  File \"/usr/local/lib/python3.5/dist-packages/flask/_compat.py\", line 33, in reraise\n",
      "    raise value\n",
      "  File \"/usr/local/lib/python3.5/dist-packages/flask/app.py\", line 1612, in full_dispatch_request\n",
      "    rv = self.dispatch_request()\n",
      "  File \"/usr/local/lib/python3.5/dist-packages/flask/app.py\", line 1598, in dispatch_request\n",
      "    return self.view_functions[rule.endpoint](**req.view_args)\n",
      "  File \"/usr/local/lib/python3.5/dist-packages/dash/dash.py\", line 558, in dispatch\n",
      "    return self.callback_map[target_id]['callback'](*args)\n",
      "  File \"/usr/local/lib/python3.5/dist-packages/dash/dash.py\", line 515, in add_context\n",
      "    output_value = func(*args, **kwargs)\n",
      "  File \"<ipython-input-24-45bfb2ec72c7>\", line 129, in gen_loss\n",
      "    x=get_xs(),\n",
      "NameError: name 'get_xs' is not defined\n",
      "127.0.0.1 - - [26/Jun/2018 15:45:19] \"POST /_dash-update-component HTTP/1.1\" 500 -\n",
      "[2018-06-26 15:45:19,596] ERROR in app: Exception on /_dash-update-component [POST]\n",
      "Traceback (most recent call last):\n",
      "  File \"/usr/local/lib/python3.5/dist-packages/flask/app.py\", line 1982, in wsgi_app\n",
      "    response = self.full_dispatch_request()\n",
      "  File \"/usr/local/lib/python3.5/dist-packages/flask/app.py\", line 1614, in full_dispatch_request\n",
      "    rv = self.handle_user_exception(e)\n",
      "  File \"/usr/local/lib/python3.5/dist-packages/flask/app.py\", line 1517, in handle_user_exception\n",
      "    reraise(exc_type, exc_value, tb)\n",
      "  File \"/usr/local/lib/python3.5/dist-packages/flask/_compat.py\", line 33, in reraise\n",
      "    raise value\n",
      "  File \"/usr/local/lib/python3.5/dist-packages/flask/app.py\", line 1612, in full_dispatch_request\n",
      "    rv = self.dispatch_request()\n",
      "  File \"/usr/local/lib/python3.5/dist-packages/flask/app.py\", line 1598, in dispatch_request\n",
      "    return self.view_functions[rule.endpoint](**req.view_args)\n",
      "  File \"/usr/local/lib/python3.5/dist-packages/dash/dash.py\", line 558, in dispatch\n",
      "    return self.callback_map[target_id]['callback'](*args)\n",
      "  File \"/usr/local/lib/python3.5/dist-packages/dash/dash.py\", line 515, in add_context\n",
      "    output_value = func(*args, **kwargs)\n",
      "  File \"<ipython-input-24-45bfb2ec72c7>\", line 115, in gen_cost\n",
      "    child = \"Test data: %f\" % get_cost()\n",
      "  File \"<ipython-input-24-45bfb2ec72c7>\", line 108, in get_cost\n",
      "    cost += random.random()\n",
      "NameError: name 'random' is not defined\n",
      "127.0.0.1 - - [26/Jun/2018 15:45:19] \"POST /_dash-update-component HTTP/1.1\" 500 -\n",
      "[2018-06-26 15:45:22,560] ERROR in app: Exception on /_dash-update-component [POST]\n",
      "Traceback (most recent call last):\n",
      "  File \"/usr/local/lib/python3.5/dist-packages/flask/app.py\", line 1982, in wsgi_app\n",
      "    response = self.full_dispatch_request()\n",
      "  File \"/usr/local/lib/python3.5/dist-packages/flask/app.py\", line 1614, in full_dispatch_request\n",
      "    rv = self.handle_user_exception(e)\n",
      "  File \"/usr/local/lib/python3.5/dist-packages/flask/app.py\", line 1517, in handle_user_exception\n",
      "    reraise(exc_type, exc_value, tb)\n",
      "  File \"/usr/local/lib/python3.5/dist-packages/flask/_compat.py\", line 33, in reraise\n",
      "    raise value\n",
      "  File \"/usr/local/lib/python3.5/dist-packages/flask/app.py\", line 1612, in full_dispatch_request\n",
      "    rv = self.dispatch_request()\n",
      "  File \"/usr/local/lib/python3.5/dist-packages/flask/app.py\", line 1598, in dispatch_request\n",
      "    return self.view_functions[rule.endpoint](**req.view_args)\n",
      "  File \"/usr/local/lib/python3.5/dist-packages/dash/dash.py\", line 558, in dispatch\n",
      "    return self.callback_map[target_id]['callback'](*args)\n",
      "  File \"/usr/local/lib/python3.5/dist-packages/dash/dash.py\", line 515, in add_context\n",
      "    output_value = func(*args, **kwargs)\n",
      "  File \"<ipython-input-24-45bfb2ec72c7>\", line 129, in gen_loss\n",
      "    x=get_xs(),\n",
      "NameError: name 'get_xs' is not defined\n",
      "127.0.0.1 - - [26/Jun/2018 15:45:22] \"POST /_dash-update-component HTTP/1.1\" 500 -\n",
      "[2018-06-26 15:45:22,570] ERROR in app: Exception on /_dash-update-component [POST]\n",
      "Traceback (most recent call last):\n",
      "  File \"/usr/local/lib/python3.5/dist-packages/flask/app.py\", line 1982, in wsgi_app\n",
      "    response = self.full_dispatch_request()\n",
      "  File \"/usr/local/lib/python3.5/dist-packages/flask/app.py\", line 1614, in full_dispatch_request\n",
      "    rv = self.handle_user_exception(e)\n",
      "  File \"/usr/local/lib/python3.5/dist-packages/flask/app.py\", line 1517, in handle_user_exception\n",
      "    reraise(exc_type, exc_value, tb)\n",
      "  File \"/usr/local/lib/python3.5/dist-packages/flask/_compat.py\", line 33, in reraise\n",
      "    raise value\n",
      "  File \"/usr/local/lib/python3.5/dist-packages/flask/app.py\", line 1612, in full_dispatch_request\n",
      "    rv = self.dispatch_request()\n",
      "  File \"/usr/local/lib/python3.5/dist-packages/flask/app.py\", line 1598, in dispatch_request\n",
      "    return self.view_functions[rule.endpoint](**req.view_args)\n",
      "  File \"/usr/local/lib/python3.5/dist-packages/dash/dash.py\", line 558, in dispatch\n",
      "    return self.callback_map[target_id]['callback'](*args)\n",
      "  File \"/usr/local/lib/python3.5/dist-packages/dash/dash.py\", line 515, in add_context\n",
      "    output_value = func(*args, **kwargs)\n",
      "  File \"<ipython-input-24-45bfb2ec72c7>\", line 115, in gen_cost\n",
      "    child = \"Test data: %f\" % get_cost()\n",
      "  File \"<ipython-input-24-45bfb2ec72c7>\", line 108, in get_cost\n",
      "    cost += random.random()\n",
      "NameError: name 'random' is not defined\n",
      "127.0.0.1 - - [26/Jun/2018 15:45:22] \"POST /_dash-update-component HTTP/1.1\" 500 -\n",
      "[2018-06-26 15:45:24,267] ERROR in app: Exception on /_dash-update-component [POST]\n",
      "Traceback (most recent call last):\n",
      "  File \"/usr/local/lib/python3.5/dist-packages/flask/app.py\", line 1982, in wsgi_app\n",
      "    response = self.full_dispatch_request()\n",
      "  File \"/usr/local/lib/python3.5/dist-packages/flask/app.py\", line 1614, in full_dispatch_request\n",
      "    rv = self.handle_user_exception(e)\n",
      "  File \"/usr/local/lib/python3.5/dist-packages/flask/app.py\", line 1517, in handle_user_exception\n",
      "    reraise(exc_type, exc_value, tb)\n",
      "  File \"/usr/local/lib/python3.5/dist-packages/flask/_compat.py\", line 33, in reraise\n",
      "    raise value\n",
      "  File \"/usr/local/lib/python3.5/dist-packages/flask/app.py\", line 1612, in full_dispatch_request\n",
      "    rv = self.dispatch_request()\n",
      "  File \"/usr/local/lib/python3.5/dist-packages/flask/app.py\", line 1598, in dispatch_request\n",
      "    return self.view_functions[rule.endpoint](**req.view_args)\n",
      "  File \"/usr/local/lib/python3.5/dist-packages/dash/dash.py\", line 558, in dispatch\n",
      "    return self.callback_map[target_id]['callback'](*args)\n",
      "  File \"/usr/local/lib/python3.5/dist-packages/dash/dash.py\", line 515, in add_context\n",
      "    output_value = func(*args, **kwargs)\n",
      "  File \"<ipython-input-24-45bfb2ec72c7>\", line 115, in gen_cost\n",
      "    child = \"Test data: %f\" % get_cost()\n",
      "  File \"<ipython-input-24-45bfb2ec72c7>\", line 108, in get_cost\n",
      "    cost += random.random()\n",
      "NameError: name 'random' is not defined\n",
      "127.0.0.1 - - [26/Jun/2018 15:45:24] \"POST /_dash-update-component HTTP/1.1\" 500 -\n",
      "[2018-06-26 15:45:24,277] ERROR in app: Exception on /_dash-update-component [POST]\n",
      "Traceback (most recent call last):\n",
      "  File \"/usr/local/lib/python3.5/dist-packages/flask/app.py\", line 1982, in wsgi_app\n",
      "    response = self.full_dispatch_request()\n",
      "  File \"/usr/local/lib/python3.5/dist-packages/flask/app.py\", line 1614, in full_dispatch_request\n",
      "    rv = self.handle_user_exception(e)\n",
      "  File \"/usr/local/lib/python3.5/dist-packages/flask/app.py\", line 1517, in handle_user_exception\n",
      "    reraise(exc_type, exc_value, tb)\n",
      "  File \"/usr/local/lib/python3.5/dist-packages/flask/_compat.py\", line 33, in reraise\n",
      "    raise value\n",
      "  File \"/usr/local/lib/python3.5/dist-packages/flask/app.py\", line 1612, in full_dispatch_request\n",
      "    rv = self.dispatch_request()\n",
      "  File \"/usr/local/lib/python3.5/dist-packages/flask/app.py\", line 1598, in dispatch_request\n",
      "    return self.view_functions[rule.endpoint](**req.view_args)\n",
      "  File \"/usr/local/lib/python3.5/dist-packages/dash/dash.py\", line 558, in dispatch\n",
      "    return self.callback_map[target_id]['callback'](*args)\n",
      "  File \"/usr/local/lib/python3.5/dist-packages/dash/dash.py\", line 515, in add_context\n",
      "    output_value = func(*args, **kwargs)\n",
      "  File \"<ipython-input-24-45bfb2ec72c7>\", line 129, in gen_loss\n",
      "    x=get_xs(),\n",
      "NameError: name 'get_xs' is not defined\n"
     ]
    },
    {
     "name": "stderr",
     "output_type": "stream",
     "text": [
      "127.0.0.1 - - [26/Jun/2018 15:45:24] \"POST /_dash-update-component HTTP/1.1\" 500 -\n",
      "[2018-06-26 15:45:25,579] ERROR in app: Exception on /_dash-update-component [POST]\n",
      "Traceback (most recent call last):\n",
      "  File \"/usr/local/lib/python3.5/dist-packages/flask/app.py\", line 1982, in wsgi_app\n",
      "    response = self.full_dispatch_request()\n",
      "  File \"/usr/local/lib/python3.5/dist-packages/flask/app.py\", line 1614, in full_dispatch_request\n",
      "    rv = self.handle_user_exception(e)\n",
      "  File \"/usr/local/lib/python3.5/dist-packages/flask/app.py\", line 1517, in handle_user_exception\n",
      "    reraise(exc_type, exc_value, tb)\n",
      "  File \"/usr/local/lib/python3.5/dist-packages/flask/_compat.py\", line 33, in reraise\n",
      "    raise value\n",
      "  File \"/usr/local/lib/python3.5/dist-packages/flask/app.py\", line 1612, in full_dispatch_request\n",
      "    rv = self.dispatch_request()\n",
      "  File \"/usr/local/lib/python3.5/dist-packages/flask/app.py\", line 1598, in dispatch_request\n",
      "    return self.view_functions[rule.endpoint](**req.view_args)\n",
      "  File \"/usr/local/lib/python3.5/dist-packages/dash/dash.py\", line 558, in dispatch\n",
      "    return self.callback_map[target_id]['callback'](*args)\n",
      "  File \"/usr/local/lib/python3.5/dist-packages/dash/dash.py\", line 515, in add_context\n",
      "    output_value = func(*args, **kwargs)\n",
      "  File \"<ipython-input-24-45bfb2ec72c7>\", line 129, in gen_loss\n",
      "    x=get_xs(),\n",
      "NameError: name 'get_xs' is not defined\n",
      "127.0.0.1 - - [26/Jun/2018 15:45:25] \"POST /_dash-update-component HTTP/1.1\" 500 -\n",
      "[2018-06-26 15:45:25,599] ERROR in app: Exception on /_dash-update-component [POST]\n",
      "Traceback (most recent call last):\n",
      "  File \"/usr/local/lib/python3.5/dist-packages/flask/app.py\", line 1982, in wsgi_app\n",
      "    response = self.full_dispatch_request()\n",
      "  File \"/usr/local/lib/python3.5/dist-packages/flask/app.py\", line 1614, in full_dispatch_request\n",
      "    rv = self.handle_user_exception(e)\n",
      "  File \"/usr/local/lib/python3.5/dist-packages/flask/app.py\", line 1517, in handle_user_exception\n",
      "    reraise(exc_type, exc_value, tb)\n",
      "  File \"/usr/local/lib/python3.5/dist-packages/flask/_compat.py\", line 33, in reraise\n",
      "    raise value\n",
      "  File \"/usr/local/lib/python3.5/dist-packages/flask/app.py\", line 1612, in full_dispatch_request\n",
      "    rv = self.dispatch_request()\n",
      "  File \"/usr/local/lib/python3.5/dist-packages/flask/app.py\", line 1598, in dispatch_request\n",
      "    return self.view_functions[rule.endpoint](**req.view_args)\n",
      "  File \"/usr/local/lib/python3.5/dist-packages/dash/dash.py\", line 558, in dispatch\n",
      "    return self.callback_map[target_id]['callback'](*args)\n",
      "  File \"/usr/local/lib/python3.5/dist-packages/dash/dash.py\", line 515, in add_context\n",
      "    output_value = func(*args, **kwargs)\n",
      "  File \"<ipython-input-24-45bfb2ec72c7>\", line 115, in gen_cost\n",
      "    child = \"Test data: %f\" % get_cost()\n",
      "  File \"<ipython-input-24-45bfb2ec72c7>\", line 108, in get_cost\n",
      "    cost += random.random()\n",
      "NameError: name 'random' is not defined\n",
      "127.0.0.1 - - [26/Jun/2018 15:45:25] \"POST /_dash-update-component HTTP/1.1\" 500 -\n",
      "[2018-06-26 15:45:27,297] ERROR in app: Exception on /_dash-update-component [POST]\n",
      "Traceback (most recent call last):\n",
      "  File \"/usr/local/lib/python3.5/dist-packages/flask/app.py\", line 1982, in wsgi_app\n",
      "    response = self.full_dispatch_request()\n",
      "  File \"/usr/local/lib/python3.5/dist-packages/flask/app.py\", line 1614, in full_dispatch_request\n",
      "    rv = self.handle_user_exception(e)\n",
      "  File \"/usr/local/lib/python3.5/dist-packages/flask/app.py\", line 1517, in handle_user_exception\n",
      "    reraise(exc_type, exc_value, tb)\n",
      "  File \"/usr/local/lib/python3.5/dist-packages/flask/_compat.py\", line 33, in reraise\n",
      "    raise value\n",
      "  File \"/usr/local/lib/python3.5/dist-packages/flask/app.py\", line 1612, in full_dispatch_request\n",
      "    rv = self.dispatch_request()\n",
      "  File \"/usr/local/lib/python3.5/dist-packages/flask/app.py\", line 1598, in dispatch_request\n",
      "    return self.view_functions[rule.endpoint](**req.view_args)\n",
      "  File \"/usr/local/lib/python3.5/dist-packages/dash/dash.py\", line 558, in dispatch\n",
      "    return self.callback_map[target_id]['callback'](*args)\n",
      "  File \"/usr/local/lib/python3.5/dist-packages/dash/dash.py\", line 515, in add_context\n",
      "    output_value = func(*args, **kwargs)\n",
      "  File \"<ipython-input-24-45bfb2ec72c7>\", line 115, in gen_cost\n",
      "    child = \"Test data: %f\" % get_cost()\n",
      "  File \"<ipython-input-24-45bfb2ec72c7>\", line 108, in get_cost\n",
      "    cost += random.random()\n",
      "NameError: name 'random' is not defined\n",
      "127.0.0.1 - - [26/Jun/2018 15:45:27] \"POST /_dash-update-component HTTP/1.1\" 500 -\n",
      "[2018-06-26 15:45:27,305] ERROR in app: Exception on /_dash-update-component [POST]\n",
      "Traceback (most recent call last):\n",
      "  File \"/usr/local/lib/python3.5/dist-packages/flask/app.py\", line 1982, in wsgi_app\n",
      "    response = self.full_dispatch_request()\n",
      "  File \"/usr/local/lib/python3.5/dist-packages/flask/app.py\", line 1614, in full_dispatch_request\n",
      "    rv = self.handle_user_exception(e)\n",
      "  File \"/usr/local/lib/python3.5/dist-packages/flask/app.py\", line 1517, in handle_user_exception\n",
      "    reraise(exc_type, exc_value, tb)\n",
      "  File \"/usr/local/lib/python3.5/dist-packages/flask/_compat.py\", line 33, in reraise\n",
      "    raise value\n",
      "  File \"/usr/local/lib/python3.5/dist-packages/flask/app.py\", line 1612, in full_dispatch_request\n",
      "    rv = self.dispatch_request()\n",
      "  File \"/usr/local/lib/python3.5/dist-packages/flask/app.py\", line 1598, in dispatch_request\n",
      "    return self.view_functions[rule.endpoint](**req.view_args)\n",
      "  File \"/usr/local/lib/python3.5/dist-packages/dash/dash.py\", line 558, in dispatch\n",
      "    return self.callback_map[target_id]['callback'](*args)\n",
      "  File \"/usr/local/lib/python3.5/dist-packages/dash/dash.py\", line 515, in add_context\n",
      "    output_value = func(*args, **kwargs)\n",
      "  File \"<ipython-input-24-45bfb2ec72c7>\", line 129, in gen_loss\n",
      "    x=get_xs(),\n",
      "NameError: name 'get_xs' is not defined\n",
      "127.0.0.1 - - [26/Jun/2018 15:45:27] \"POST /_dash-update-component HTTP/1.1\" 500 -\n",
      "[2018-06-26 15:45:28,664] ERROR in app: Exception on /_dash-update-component [POST]\n",
      "Traceback (most recent call last):\n",
      "  File \"/usr/local/lib/python3.5/dist-packages/flask/app.py\", line 1982, in wsgi_app\n",
      "    response = self.full_dispatch_request()\n",
      "  File \"/usr/local/lib/python3.5/dist-packages/flask/app.py\", line 1614, in full_dispatch_request\n",
      "    rv = self.handle_user_exception(e)\n",
      "  File \"/usr/local/lib/python3.5/dist-packages/flask/app.py\", line 1517, in handle_user_exception\n",
      "    reraise(exc_type, exc_value, tb)\n",
      "  File \"/usr/local/lib/python3.5/dist-packages/flask/_compat.py\", line 33, in reraise\n",
      "    raise value\n",
      "  File \"/usr/local/lib/python3.5/dist-packages/flask/app.py\", line 1612, in full_dispatch_request\n",
      "    rv = self.dispatch_request()\n",
      "  File \"/usr/local/lib/python3.5/dist-packages/flask/app.py\", line 1598, in dispatch_request\n",
      "    return self.view_functions[rule.endpoint](**req.view_args)\n",
      "  File \"/usr/local/lib/python3.5/dist-packages/dash/dash.py\", line 558, in dispatch\n",
      "    return self.callback_map[target_id]['callback'](*args)\n",
      "  File \"/usr/local/lib/python3.5/dist-packages/dash/dash.py\", line 515, in add_context\n",
      "    output_value = func(*args, **kwargs)\n",
      "  File \"<ipython-input-24-45bfb2ec72c7>\", line 129, in gen_loss\n",
      "    x=get_xs(),\n",
      "NameError: name 'get_xs' is not defined\n",
      "127.0.0.1 - - [26/Jun/2018 15:45:28] \"POST /_dash-update-component HTTP/1.1\" 500 -\n",
      "[2018-06-26 15:45:28,672] ERROR in app: Exception on /_dash-update-component [POST]\n",
      "Traceback (most recent call last):\n",
      "  File \"/usr/local/lib/python3.5/dist-packages/flask/app.py\", line 1982, in wsgi_app\n",
      "    response = self.full_dispatch_request()\n",
      "  File \"/usr/local/lib/python3.5/dist-packages/flask/app.py\", line 1614, in full_dispatch_request\n",
      "    rv = self.handle_user_exception(e)\n",
      "  File \"/usr/local/lib/python3.5/dist-packages/flask/app.py\", line 1517, in handle_user_exception\n",
      "    reraise(exc_type, exc_value, tb)\n",
      "  File \"/usr/local/lib/python3.5/dist-packages/flask/_compat.py\", line 33, in reraise\n",
      "    raise value\n",
      "  File \"/usr/local/lib/python3.5/dist-packages/flask/app.py\", line 1612, in full_dispatch_request\n",
      "    rv = self.dispatch_request()\n",
      "  File \"/usr/local/lib/python3.5/dist-packages/flask/app.py\", line 1598, in dispatch_request\n",
      "    return self.view_functions[rule.endpoint](**req.view_args)\n",
      "  File \"/usr/local/lib/python3.5/dist-packages/dash/dash.py\", line 558, in dispatch\n",
      "    return self.callback_map[target_id]['callback'](*args)\n",
      "  File \"/usr/local/lib/python3.5/dist-packages/dash/dash.py\", line 515, in add_context\n",
      "    output_value = func(*args, **kwargs)\n",
      "  File \"<ipython-input-24-45bfb2ec72c7>\", line 115, in gen_cost\n",
      "    child = \"Test data: %f\" % get_cost()\n",
      "  File \"<ipython-input-24-45bfb2ec72c7>\", line 108, in get_cost\n",
      "    cost += random.random()\n",
      "NameError: name 'random' is not defined\n"
     ]
    },
    {
     "name": "stderr",
     "output_type": "stream",
     "text": [
      "127.0.0.1 - - [26/Jun/2018 15:45:28] \"POST /_dash-update-component HTTP/1.1\" 500 -\n"
     ]
    }
   ],
   "source": [
    "show_app(app)"
   ]
  },
  {
   "cell_type": "code",
   "execution_count": 31,
   "metadata": {},
   "outputs": [
    {
     "data": {
      "text/html": [
       "\n",
       "        <iframe\n",
       "            width=\"1000\"\n",
       "            height=\"1000\"\n",
       "            src=\"http://localhost:8050\"\n",
       "            frameborder=\"0\"\n",
       "            allowfullscreen\n",
       "        ></iframe>\n",
       "        "
      ],
      "text/plain": [
       "<IPython.lib.display.IFrame at 0x7faa44244a58>"
      ]
     },
     "execution_count": 31,
     "metadata": {},
     "output_type": "execute_result"
    }
   ],
   "source": [
    "from IPython.display import IFrame\n",
    "IFrame('http://localhost:8050', width=1000, height=1000)"
   ]
  },
  {
   "cell_type": "code",
   "execution_count": null,
   "metadata": {},
   "outputs": [],
   "source": []
  }
 ],
 "metadata": {
  "kernelspec": {
   "display_name": "Python 3",
   "language": "python",
   "name": "python3"
  },
  "language_info": {
   "codemirror_mode": {
    "name": "ipython",
    "version": 3
   },
   "file_extension": ".py",
   "mimetype": "text/x-python",
   "name": "python",
   "nbconvert_exporter": "python",
   "pygments_lexer": "ipython3",
   "version": "3.5.2"
  }
 },
 "nbformat": 4,
 "nbformat_minor": 2
}
